Workbook

Sheet 사용법
A1: HS코드 분류 baseline 측정표 v3
A2: 공통 항목은 [케이스목록] 한 곳에만 입력하면 측정기록·조건B 시트로 자동 연결됩니다.
A4: 시트 구조
A5: 케이스목록 — 결정례번호·품명·정답HSK·물품설명을 여기 한 번만 입력. 나머지 시트가 자동으로 끌어씁니다.
A6: 측정기록 — 조건 A(상세 물품설명 입력). P1·P2 응답만 기록
A7: 조건B_품명only — 조건 B(품명 원문 입력). P1 응답만 기록
A8: 일관성 — 같은 질문 3회 반복
A9: 결과요약 — 전부 자동 계산
A10: 측정조건 — 모델·설정을 기록. 재현 가능성의 근거이므로 반드시 채우세요
A12: 색 규칙
A13: 노란색 = 직접 입력 / 연두색 = 케이스목록에서 자동 연결(수정 금지) / 회색 = 자동 계산
A15: 유효_A · 유효_B 열이 핵심입니다
... A51: 이 한 줄들이 30건 뒤에 유형으로 뭉치고, 그것이 만들 시스템의 기능 목록이 됩니다.

Sheet 케이스목록
A1: 케이스목록 — 공통 항목 단일 입력
A2: 여기 입력한 값이 측정기록·조건B 시트로 자동 전달됩니다. 오염된 건은 유효_A / 유효_B를 X로.
A3: 번호 | B3: 결정례 번호 | C3: 품명 원문 (조건B 입력값) | D3: 정답 HSK | E3: 물품설명 (조건A 입력값) | F3: 물품설명 출처 | G3: 품명유형 | H3: 유효 A | I3: 유효 B | J3: 제외 사유
A5: 1 | B5: 품목분류2과-4285 | C5: 친환경 액상 제설제 SDI 200 | D5: 3820002000 | E5: 도로에 쌓인 눈 또는 결빙 등의 제거를 위한 액상 제설제로, 무수염화칼슘, 염화나트륨, 글리세린, 글루콘산소다, pH 조정제, 물로 조제한 액상 | F5: 원문 | G5: 품명명확 | H5: X | I5: X | J5: 검색 ON 상태에서 측정(AI Studio 전환 전). 재측정 필요
A6: 2 | B6: 품목분류2과-4144 | C6: Silica Coating Liquid; NS1033011 Grey Primer | D6: 3207209000 | E6: Silica sol, Methyltrimethoxysilane, 안료(Titanium dioxide, Copper chromite black spinel 등), Isopropyl alcohol, Formic acid, Water로 혼합·조제된 회색계 점조 액상. 용도: 프라이팬 등의 세라믹 코팅(제시한 카탈로그에서 경화 온도 180~300℃) | F6: 원문 | G6: 품번only | H6: O | I6: O
A7: 3 | B7: 품목분류2과-3140 | C7: (재확인 필요 — 기존 입력은 관세율표 호 문언) | D7: 0902100000 | E7: 파쇄상의 녹차에 소량의 합성향과 자스민꽃을 혼합하여 수지제 팩에 소매포장한 것(내용량 150g). 용도: 온수에 침출하여 음용 | F7: 원문 | G7: 품명명확 | H7: O | I7: X | J7: 결정례 품명 칸 자체에 소호 문언이 그대로 기재된 케이스. 입력 오류가 아니라 데이터 특성상 정답 누설
A8: 4 | B8: 품목분류1과-3731 | C8: 건담 카드게임 스타트덱 건담 어셈블 세트 Heroic Beginnings【ST01A】 | D8: 9504400000 | E8: 건담 게임용 카드 1묶음(50장), 건담 조립용 키트 3종, 설명서 2매(게임용·조립용)가 소매포장되어 제시된 물품. 카드에 표시된 공격력과 수비력을 비교해 승부를 내는 방식으로 게임을 진행함. 조립하여 완성한 미니어처 3종은 카드게임 규칙과 무관한 연출용. 업체 제시 가격비중은 카드 약 250엔, 조립키트 약 480엔 | F8: 원문 | G8: 품명명확 | H8: O | I8: O
A9: 5 | B9: 품목분류2과-31881 | C9: D-100 Wash Solution | D9: 2850003000 | E9: 아지드화나트륨(Sodium azide, CAS No. 26628-22-8) 0.1% 미만을 물에 용해한 무색투명한 액상을 플라스틱 용기에 소매포장한 것(내용량 3,300ml). 용도: 시험용 검체 주입 간 검체 바늘 및 컬럼 세척 등 | F9: 원문 | G9: 품번only | H9: O | I9: O
A10: 6 | B10: 품목분류3과-3310 | C10: 고순도 제약용 호스 어셈블리 SXW | D10: 3917399000 | E10: ㅇ 실리콘(Silicone) 재질의 호스 또는 PTFE(Polytetrafluoroethylene) 재질의 호스로서, 양 끝단에는 스테인리스 스틸 연결구가 부착됨 - (용도) 유체 이송(배지, 약액, 최종원액 등)용으로 제약(백신) 제조공정*의 여러 장비**에 연결되어 사용됨 * 세포에서 항체를 만들고, 불순물과 바이러스를 제거한 뒤 농축‧조성 조정을 거쳐 최종 용기에 무균 충전하는 공정 ** Chromatography skid, Virus filter skid, UF/DF skid, Filling station ㅇ SXW : 약 길이 1200㎜, 직경 48㎜, 파열압 0.345 ∼ 1.03(㎫), 실리콘재질, 스테인리스 스틸 와이어로 보강됨 ※ 제조사 홈페이지: “의약품, 화장품 및 식품이송에 적합” | F10: 원문 | G10: 품명명확 | H10: O | I10: O
A11: 7 | B11: 품목분류3과-3040 | C11: CUSHION COMPACT 외용기, 내용기 ,메쉬링(+리드씰) | D11: 3923100000 | E11: ㅇ 물품개요 - 화장품 CUSHION COMPACT 용기를 구성하는 ① 외용기, ② 내용기, ③ 매쉬링(리드씰 포함)이 미조립 상태로 제시, 각 구성요소를 결합하면 케이스 완성품이 됨 (파운데이션 내용물 미포함) - 구성요소는 각 개별박스에 벌크 포장된 형태로 함께 제시 - 구성요소 ① 외용기(ABS, AS, GLASS) : 내부에 거울이 부착된 화장품 외부 용기 ② 내용기(PP) : 화장품(파운데이션)을 담는 내부 용기 ③ 매쉬링(리드씰 포함)(NYLON, PP/PE, AL) : 화장품이 균일하게 도포되도록 돕는 매쉬망과 고정링에 제품보호용 씰(제거후 사용)이 부착됨 ㅇ 수입 후 제조공정 - 원료 칭량(Weighing) → 교반 → 믹싱 → 내용기 충전(몰드진입, 용기공급, 충전, 매쉬망, 실링, 라벨링, 배출) → 외용기 결합 → 포장 | F11: 원문 | G11: 품명명확 | H11: O | I11: O
A12: 8 | B12: 품목분류4과-1253 | C12: MIRAMER PU5000; MIRAMER PU5000; 200KG DRUM | D12: 3909500000 | E12: ㅇ (개요) ① Polyurethane acrylate*(우레탄계 프리폴리머) 35~40%, ② 2-Propenoic acid reaction products with pentaerythritol(미반응원료) 10~15%, ③ Ethoxylated pentaerythritol tetraacrylate(점도조정제, 희석제) 50%로 구성된 무색투명한 점조액상 * 성분명 : 2-[[(1-Oxo-2-propenyl)oxy]methyl]-2-[[[[[[1,3,3-trimethyl-5- [[[3-[(1-oxo-2-propenyl)oxy]-2,2-bis[[(1-oxo-2-propenyl)oxy]methyl]propoxy]carbonyl]amino]cyclohexyl]methyl]amino]carbonyl]oxy]methyl]-1,3-propanediyl 2-propenoate ㅇ (제조공정) 원료 투입 → 반응 → 여과 및 포장 ㅇ (원료) | F12: 원문 | G12: 품번only | H12: O | I12: O
A13: 9 | B13: 품목분류4과-1933 | C13: LOCAL FIRE FIGHTING SYSTEM; WATER MIST SYSTEM;MIST | D13: 8424899000 | E13: ㅇ 물품개요 - 안건 물품은 선박의 기관실 등에서 화재 발생시 화재감지 신호에 따라 펌프가 작동하여 물을 미립화하여 고압으로 분무함으로써 화재를 진압하는 화재 진압 시스템(소화수 탱크는 미제시됨) ㅇ 용도 : 선박 기관실(주기관, 발전기, 보일러 등 고위험 설비)내의 화재 방호 ㅇ 작동원리 : 물 입자를 미분무수화하여 표면적을 증가시키고 열을 흡수함과 동시에 물의 증발을 최대화하여 냉각 효과로 소화 ㅇ 주요 구성요소 및 기능 - 펌프 : 화재 발생시 노즐로 소화수를 전달 - 컨트롤판넬 : 시스템 제어 및 상태관리 - 미분수 노즐 : 소화수(물)를 분사하여 화재를 진압하는 장치 - 배관 및 밸브 : 제어 신호에 따라 소화수 공급 및 배관 라인 개폐 - 화재감지기 : 화재 발생시 연기, 열, 화염 등을 감지하여 컨트롤판넬로 전달 - (미제시) 소화수 탱크 : 소화수를 저장하는 장치이며 펌프와 배관으로 연결 | F13: 원문 | G13: 품명명확 | H13: O | I13: O
A14: 10 | B14: 품목분류3과-3871 | C14: PC WITH SOFT; 6V9Y0048; FC-E23W-G26CV9-SSDMODE; | D14: 8471501000 | E14: ㅇ 물품 개요 - 반도체 세정장비*(SU-3200)에 사용되는 산업용 컴퓨터로 제어 프로그램이 설치되어 수입 * 반도체 제조공정 중 발생한 Wafer 표면의 각종 이물질을 화공약품을 이용하여 제거 ㅇ 기능 및 용도: 장비 전체 운영의 중앙 제어, 장비 상태 모니터링 및 보호, 데이터 수집 및 로깅, 장비 최적화·스케줄링 기능, 보안·사용자 권한 관리, 서브 시스템과의 통신 및 제어 명령 분배 ㅇ 일반 프로그램 설치 가능 여부 - 신청 물품은 Windows 운영체제가 설치된 산업용 컴퓨터로서, 일반 PC와 동일하게 다양한 프로그램의 설치 및 실행이 가능하며, 프로그램 설치와 관련된 기술적 제한 없음 ㅇ 제어 방식: 신청 물품이 장치 운용을 위한 명령*을 VME Controller에 지시 → VME Controller는 다시 각 모듈**에 동작***을 지시 → 모듈 수행에 따른 각종 데이터를 다시 VME Controller가 취합 후 신청 물품으로 송부 * 사용자 입력 및 시스템 조건에 따른 장비의 가동, 정지, 중단 ** 로봇 컨트톨러, 반송 장치, 챔버, 밸브, 센서 등 *** 로봇 동작(Move, Pick up, Place 등), Motor/Pump 제어(위치, 속도 관련 정보) 등 | F14: 원문 | G14: 품명명확 | H14: O | I14: O
A15: 11 | B15: 품목분류2과-1654 | C15: KP-SOL-90 | D15: 2710129000 | E15: ㅇ 물품개요 - 수소처리된 경질 나프타[Naphtha(petroleum), hydrotreated light] (85%~95%), 방향족 탄화수소 혼합물* (1%~10%)을 혼합한 무색 투명한 액상[비방향족 성분 중량이 방향족 성분 중량을 초과, ISO 3405방법으로 210℃에서 90%이상 증류] * Mixed xylene : 에틸벤젠(Ethylbenzene) 50~60%, 크실렌(Xylene) 40~50% - 용도: 산업용 용제 | F15: 원문 | G15: 품번only | H15: O | I15: O
A16: 12 | B16: 품목분류2과-1460 | C16: FROZEN GINGER WITH SUGAR | D16: 2008999000 | E16: ㅇ 물품개요 - 원상의 생강을 끓는 물에 담가 세척하고 절단하여 설탕 시럽(끓는 물에 설탕을 녹여 만든 시럽을 용기 3개에 담은 후 순차적으로 침적)에 침적한 후 잔류 시럽을 배출한 생강 채 50%에 설탕 50%를 넣어 포장하여 냉동한 것 - 용도 : 식용(생강차 제조용) - 분석결과 ▪시료 : 수분 약 36.9% ①자당 약 56% ②자당 약 50% / 시럽 자당 약 59% ▪생강(미 농무성) : 수분 78.9%, 당 1.7% - 제조공정 원상의 생강 ⇒ 세척(끓는 물에 담금/살균 및 전분 제거) ⇒ 채 썰기 ⇒ 설탕 시럽에 3회 침적(끓는 물에 설탕을 녹여 만든 시럽을 용기* 3개에 나눠 담은 후 생강 채를 각 시럽에 순차적으로 침적) ⇒ 시럽 배출 ⇒ 설탕 혼합 ⇒ 포장 ⇒ 냉동 ※ 생강 채를 시럽에 넣어 끓이지 않는 이유 - 생강 채를 설탕 시럽에 담근 상태에서 끓이면 생강의 형태를 유지하기 어렵기 때문에, 생강 형상을 최대한 유지하기 위해 끓는 물에 설탕을 녹여 만든 시럽에 침적하는 방식으로 제조 | F16: 원문 | G16: 품명명확 | H16: O | I16: O
A17: 13 | B17: 품목분류4과-945 | C17: COOLOA; RH-CD02W | D17: 8424209000 | E17: ㅇ 물품개요 - CO₂가스를 동력원으로 화장품을 피부 표면에 미세하고 균일하게 분사하는 미용기기 - 분사 과정 중 화장품의 온도를 낮춰 피부에 쿨링감을 제공 ㅇ 주요 구성요소 및 기능 - 노즐 : CO₂가스를 제어하면서 분사 방향/각도 유지 - 냉각모듈 : 열전대소자(Peltier)*로, 화장품의 온도를 쿨링감있게 유지 * 전기를 흘리면 한쪽 면은 차가워지고 반대쪽 면은 뜨거워지는 열전소자 - 솔레노이드 밸브 : 전자제어 밸브로 가스 분사량 제어 - 디스플레이 : 배터리, 오류코드 등 상태 표시 - 트리거(방아쇠), USB-C 충전 포트, 리튬이온 배터리(3,350㎃h) 내장 등 - CO₂카트리지(미제시) : 고압 액화 CO₂가 밀봉된 소형 실린더 - 컨테이너(미제시) : 액상 화장품을 담는 용기 ㅇ 작동 원리 - 카트리지와 컨테이너 장착(미제시) → 트리거 작동 → 솔레노이드밸브가 개방되며 CO₂가스가 부품 내의 용기 안으로 이동 → 용기 내부 압력 상승 → 화장품이 노즐을 통해 약 45° 각도로 분사 - CO₂가스(극저온 냉매, -79도)의 분사로 화장품의 온도를 급속히 낮추고 이를 열전대(Peltier) 소자로 급속 가열하여 피부에 전달되는 온도(2~4도)로 유지 | F17: 원문 | G17: 품번only | H17: O | I17: O
A18: 14 | B18: 품목분류1과-876 | C18: 16mm F6.5 autofocus VIS+NIR lens; 820-20194-005 | D18: 9002119090 | E18: ㅇ 물품 개요 - 산업용 스마트카메라*의 일종인 In-sight Vision 장비에 전용되는 대물렌즈로, 측정 대상 물품의 상을 포착하여 후방(스마트 카메라 본체)에 위치한 CMOS 이미지 센서에 상을 맺게 함 * 일반적인 카메라와 달리 영상획득, 영상처리, 판단․제어 로직을 하나의 장치로 통합한 비전(vision) 측정검사 장비(제9031.4호에 분류되고 있음) ㅇ 구성 요소별 기능 ① 렌즈 : 일반렌즈와 액체 렌즈가 결합된 형태로, 포착된 피사체의 상을 스마트 카메라 본체 내부의 CMOS 이미지 센서 위에 결상시킴(본체의 CMOS 센서가 이를 디지털 신호로 변환하여 영상 데이터를 생성) ② 커넥터 : 액체 렌즈 부분의 셀을 형성하기 위해서 전력을 공급하고, 촬영 간 초점을 빠르게 전환하기 위한 제어 명령 전달 ③ 장착 부분 : Auto Focus 렌즈(쟁점물품)와 In-sight 제품(본체)을 연결하는 부분으로 인사이트 제품의 장착에 맞게 홈이 파여 있으며 제품을 연결하기 위해 볼트가 삽입된 연결부분이 있음. | F18: 원문 | G18: 품명명확 | H18: O | I18: O
A19: 15 | B19: 품목분류2과-1011 | C19: ㅇ 재우스오라쿠고에이취플라스타(살리실산); OLAKUKO - H; | D19: 3004909900 | E19: ㅇ 물품개요 - 살리실산을 주성분으로 한 황색 페이스트를 원형 스펀지 중앙에 채운 후 스트립상의 접착시트에 부착한 것을 소매포장한 것(내용량 : 100g, 12매/box) - 용도: 티눈, 굳은 살, 사마귀 제거(일반의약품) | F19: 원문 | G19: 품명명확 | H19: O | I19: O
... A34: 30 | B34: 품목분류4과-3248 | C34: 코듀로이 셔츠자켓; IKYC24W01 | D34: 6205200000 | E34: ㅇ 물품개요 - 면 직물로 만든 긴팔 상의로 실외 착용 아동용 의류 - 일정한 두께감으로 셔츠로 착용이 가능하며, 티셔츠 위에 재킷으로도 착용이 가능한 하이브리드 의류 - (형태) 전면 2개, 후면 2개에 총 4개의 세로 방향 패널이 있으며, 전면이 오픈되어 단추로 개폐되고 칼라가 있음, 밑단에 별도의 골이 진 허릿단이나 조이는 부분이 없으며 전면 가슴 부분 양쪽에 포켓이 있음, 등 부분에 영문 로고가 있음. 길이가 허리까지 오며 잠금방식이 왼편이 오른편 위로 여닫게 되어 있는 소년용 의류임 | F34: 원문 | G34: 품명명확 | H34: O | I34: O

Sheet 측정기록
A1: 조건 A — 상세 물품설명 입력 (모델 성능의 상한선)
A2: 연두색은 케이스목록 자동 연결. 노란색만 입력하세요. 조건A에는 품명·품번을 넣지 않습니다.
A3: 번호 | B3: 결정례 번호 | C3: 물품설명 (연결) | D3: 정답 HSK | E3: 유효 A | F3: 검색 사용 | G3: 결정례 인용 | H3: P1 응답코드 | I3: P1 4자리 | J3: P1 6자리 | K3: P1 10자리 | L3: P2 후보1 | M3: P2 후보2 | N3: P2 후보3 | O3: P2 Top1 6자리 | P3: P2 Top3 포함 | Q3: 오답유형 | R3: 메모 (왜 틀렸나)
A5: 1 | B5: =IF(케이스목록!$B5="","",케이스목록!$B5) -> 품목분류2과-4285 | C5: =IF(케이스목록!$E5="","",케이스목록!$E5) -> 도로에 쌓인 눈 또는 결빙 등의 제거를 위한 액상 제설제로, 무수염화칼슘, 염화나트륨, 글리세린, 글루콘산소다, pH 조정제, 물로 조제한 액상 | D5: =IF(케이스목록!$D5="","",케이스목록!$D5) -> 3820002000 | E5: =IF(케이스목록!$H5="","",케이스목록!$H5) -> X | F5: O | G5: X | H5: 3820002000 | I5: =IF(OR($D5="",$H5=""),"",IF(LEFT(SUBSTITUTE(SUBSTITUTE(SUBSTITUTE(SUBSTITUTE(SUBSTITUTE($D5,".",""),"-","")," ","")," ",""),CHAR(9),""),4)=LEFT(SUBSTITUTE(SUBSTITUTE(SUBSTITUTE(SUBSTITUTE(SUBSTITUTE($H5,".",""),"-","")," ","")," ",""),CHAR(9),""),4),1,0)) -> 1 | J5: =IF(OR($D5="",$H5=""),"",IF(LEFT(SUBSTITUTE(SUBSTITUTE(SUBSTITUTE(SUBSTITUTE(SUBSTITUTE($D5,".",""),"-","")," ","")," ",""),CHAR(9),""),6)=LEFT(SUBSTITUTE(SUBSTITUTE(SUBSTITUTE(SUBSTITUTE(SUBSTITUTE($H5,".",""),"-","")," ","")," ",""),CHAR(9),""),6),1,0)) -> 1 | K5: =IF(OR($D5="",$H5=""),"",IF(SUBSTITUTE(SUBSTITUTE(SUBSTITUTE(SUBSTITUTE(SUBSTITUTE($D5,".",""),"-","")," ","")," ",""),CHAR(9),"")=SUBSTITUTE(SUBSTITUTE(SUBSTITUTE(SUBSTITUTE(SUBSTITUTE($H5,".",""),"-","")," ","")," ",""),CHAR(9),""),1,0)) -> 1 | L5: 3820002000 | M5: 3824999090 | N5: 2827200000 | O5: =IF(OR($D5="",$L5=""),"",IF(LEFT(SUBSTITUTE(SUBSTITUTE(SUBSTITUTE(SUBSTITUTE(SUBSTITUTE($D5,".",""),"-","")," ","")," ",""),CHAR(9),""),6)=LEFT(SUBSTITUTE(SUBSTITUTE(SUBSTITUTE(SUBSTITUTE(SUBSTITUTE($L5,".",""),"-","")," ","")," ",""),CHAR(9),""),6),1,0)) -> 1 | P5: =IF(OR($D5="",$L5=""),"",IF(OR(LEFT(SUBSTITUTE(SUBSTITUTE(SUBSTITUTE(SUBSTITUTE(SUBSTITUTE($D5,".",""),"-","")," ","")," ",""),CHAR(9),""),6)=LEFT(SUBSTITUTE(SUBSTITUTE(SUBSTITUTE(SUBSTITUTE(SUBSTITUTE($L5,".",""),"-","")," ","")," ",""),CHAR(9),""),6),LEFT(SUBSTITUTE(SUBSTITUTE(SUBSTITUTE(SUBSTITUTE(SUBSTITUTE($D5,".",""),"-","")," ","")," ",""),CHAR(9),""),6)=LEFT(SUBSTITUTE(SUBSTITUTE(SUBSTITUTE(SUBSTITUTE(SUBSTITUTE($M5,".",""),"-","")," ","")," ",""),CHAR(9),""),6),LEFT(SUBSTITUTE(SUBSTITUTE(SUBSTITUTE(SUBSTITUTE(SUBSTITUTE($D5,".",""),"-","")," ","")," ",""),CHAR(9),""),6)=LEFT(SUBSTITUTE(SUBSTITUTE(SUBSTITUTE(SUBSTITUTE(SUBSTITUTE($N5,".",""),"-","")," ","")," ",""),CHAR(9),""),6)),1,0)) -> 1 | R5: (집계 제외 — 재측정 대상)
A6: 2 | B6: =IF(케이스목록!$B6="","",케이스목록!$B6) -> 품목분류2과-4144 | C6: =IF(케이스목록!$E6="","",케이스목록!$E6) -> Silica sol, Methyltrimethoxysilane, 안료(Titanium dioxide, Copper chromite black spinel 등), Isopropyl alcohol, Formic acid, Water로 혼합·조제된 회색계 점조 액상. 용도: 프라이팬 등의 세라믹 코팅(제시한 카탈로그에서 경화 온도 180~300℃) | D6: =IF(케이스목록!$D6="","",케이스목록!$D6) -> 3207209000 | E6: =IF(케이스목록!$H6="","",케이스목록!$H6) -> O | F6: X | G6: X | H6: 3824999090 | I6: =IF(OR($D6="",$H6=""),"",IF(LEFT(SUBSTITUTE(SUBSTITUTE(SUBSTITUTE(SUBSTITUTE(SUBSTITUTE($D6,".",""),"-","")," ","")," ",""),CHAR(9),""),4)=LEFT(SUBSTITUTE(SUBSTITUTE(SUBSTITUTE(SUBSTITUTE(SUBSTITUTE($H6,".",""),"-","")," ","")," ",""),CHAR(9),""),4),1,0)) -> 0 | J6: =IF(OR($D6="",$H6=""),"",IF(LEFT(SUBSTITUTE(SUBSTITUTE(SUBSTITUTE(SUBSTITUTE(SUBSTITUTE($D6,".",""),"-","")," ","")," ",""),CHAR(9),""),6)=LEFT(SUBSTITUTE(SUBSTITUTE(SUBSTITUTE(SUBSTITUTE(SUBSTITUTE($H6,".",""),"-","")," ","")," ",""),CHAR(9),""),6),1,0)) -> 0 | K6: =IF(OR($D6="",$H6=""),"",IF(SUBSTITUTE(SUBSTITUTE(SUBSTITUTE(SUBSTITUTE(SUBSTITUTE($D6,".",""),"-","")," ","")," ",""),CHAR(9),"")=SUBSTITUTE(SUBSTITUTE(SUBSTITUTE(SUBSTITUTE(SUBSTITUTE($H6,".",""),"-","")," ","")," ",""),CHAR(9),""),1,0)) -> 0 | L6: 3824999090 | M6: 3209900000 | N6: 3208909000 | O6: =IF(OR($D6="",$L6=""),"",IF(LEFT(SUBSTITUTE(SUBSTITUTE(SUBSTITUTE(SUBSTITUTE(SUBSTITUTE($D6,".",""),"-","")," ","")," ",""),CHAR(9),""),6)=LEFT(SUBSTITUTE(SUBSTITUTE(SUBSTITUTE(SUBSTITUTE(SUBSTITUTE($L6,".",""),"-","")," ","")," ",""),CHAR(9),""),6),1,0)) -> 0 | P6: =IF(OR($D6="",$L6=""),"",IF(OR(LEFT(SUBSTITUTE(SUBSTITUTE(SUBSTITUTE(SUBSTITUTE(SUBSTITUTE($D6,".",""),"-","")," ","")," ",""),CHAR(9),""),6)=LEFT(SUBSTITUTE(SUBSTITUTE(SUBSTITUTE(SUBSTITUTE(SUBSTITUTE($L6,".",""),"-","")," ","")," ",""),CHAR(9),""),6),LEFT(SUBSTITUTE(SUBSTITUTE(SUBSTITUTE(SUBSTITUTE(SUBSTITUTE($D6,".",""),"-","")," ","")," ",""),CHAR(9),""),6)=LEFT(SUBSTITUTE(SUBSTITUTE(SUBSTITUTE(SUBSTITUTE(SUBSTITUTE($M6,".",""),"-","")," ","")," ",""),CHAR(9),""),6),LEFT(SUBSTITUTE(SUBSTITUTE(SUBSTITUTE(SUBSTITUTE(SUBSTITUTE($D6,".",""),"-","")," ","")," ",""),CHAR(9),""),6)=LEFT(SUBSTITUTE(SUBSTITUTE(SUBSTITUTE(SUBSTITUTE(SUBSTITUTE($N6,".",""),"-","")," ","")," ",""),CHAR(9),""),6)),1,0)) -> 0 | Q6: 호 경합 판단 오류 | R6: 물품은 정확히 이해(프라이팬 세라믹 코팅, 실란 단량체 후경화)했으나 요업·유리공업용 조제품 관점에 도달 못 함. 후보 6개 전부 32·38류에 몰리고 정답 호는 검토조차 안 됨
A7: 3 | B7: =IF(케이스목록!$B7="","",케이스목록!$B7) -> 품목분류2과-3140 | C7: =IF(케이스목록!$E7="","",케이스목록!$E7) -> 파쇄상의 녹차에 소량의 합성향과 자스민꽃을 혼합하여 수지제 팩에 소매포장한 것(내용량 150g). 용도: 온수에 침출하여 음용 | D7: =IF(케이스목록!$D7="","",케이스목록!$D7) -> 0902100000 | E7: =IF(케이스목록!$H7="","",케이스목록!$H7) -> O | F7: X | G7: X | H7: 0902101000 | I7: =IF(OR($D7="",$H7=""),"",IF(LEFT(SUBSTITUTE(SUBSTITUTE(SUBSTITUTE(SUBSTITUTE(SUBSTITUTE($D7,".",""),"-","")," ","")," ",""),CHAR(9),""),4)=LEFT(SUBSTITUTE(SUBSTITUTE(SUBSTITUTE(SUBSTITUTE(SUBSTITUTE($H7,".",""),"-","")," ","")," ",""),CHAR(9),""),4),1,0)) -> 1 | J7: =IF(OR($D7="",$H7=""),"",IF(LEFT(SUBSTITUTE(SUBSTITUTE(SUBSTITUTE(SUBSTITUTE(SUBSTITUTE($D7,".",""),"-","")," ","")," ",""),CHAR(9),""),6)=LEFT(SUBSTITUTE(SUBSTITUTE(SUBSTITUTE(SUBSTITUTE(SUBSTITUTE($H7,".",""),"-","")," ","")," ",""),CHAR(9),""),6),1,0)) -> 1 | K7: =IF(OR($D7="",$H7=""),"",IF(SUBSTITUTE(SUBSTITUTE(SUBSTITUTE(SUBSTITUTE(SUBSTITUTE($D7,".",""),"-","")," ","")," ",""),CHAR(9),"")=SUBSTITUTE(SUBSTITUTE(SUBSTITUTE(SUBSTITUTE(SUBSTITUTE($H7,".",""),"-","")," ","")," ",""),CHAR(9),""),1,0)) -> 0 | L7: 0902101000 | M7: 0902109000 | N7: 2106909099 | O7: =IF(OR($D7="",$L7=""),"",IF(LEFT(SUBSTITUTE(SUBSTITUTE(SUBSTITUTE(SUBSTITUTE(SUBSTITUTE($D7,".",""),"-","")," ","")," ",""),CHAR(9),""),6)=LEFT(SUBSTITUTE(SUBSTITUTE(SUBSTITUTE(SUBSTITUTE(SUBSTITUTE($L7,".",""),"-","")," ","")," ",""),CHAR(9),""),6),1,0)) -> 1 | P7: =IF(OR($D7="",$L7=""),"",IF(OR(LEFT(SUBSTITUTE(SUBSTITUTE(SUBSTITUTE(SUBSTITUTE(SUBSTITUTE($D7,".",""),"-","")," ","")," ",""),CHAR(9),""),6)=LEFT(SUBSTITUTE(SUBSTITUTE(SUBSTITUTE(SUBSTITUTE(SUBSTITUTE($L7,".",""),"-","")," ","")," ",""),CHAR(9),""),6),LEFT(SUBSTITUTE(SUBSTITUTE(SUBSTITUTE(SUBSTITUTE(SUBSTITUTE($D7,".",""),"-","")," ","")," ",""),CHAR(9),""),6)=LEFT(SUBSTITUTE(SUBSTITUTE(SUBSTITUTE(SUBSTITUTE(SUBSTITUTE($M7,".",""),"-","")," ","")," ",""),CHAR(9),""),6),LEFT(SUBSTITUTE(SUBSTITUTE(SUBSTITUTE(SUBSTITUTE(SUBSTITUTE($D7,".",""),"-","")," ","")," ",""),CHAR(9),""),6)=LEFT(SUBSTITUTE(SUBSTITUTE(SUBSTITUTE(SUBSTITUTE(SUBSTITUTE($N7,".",""),"-","")," ","")," ",""),CHAR(9),""),6)),1,0)) -> 1 | Q7: 한국 고유 세번(10자리) 오류 | R7: 6자리까지 정확. 향 첨가 여부로 세번이 갈리는 한국 고유 구분에서 -1000을 골랐으나 결정은 -0000
A8: 4 | B8: =IF(케이스목록!$B8="","",케이스목록!$B8) -> 품목분류1과-3731 | C8: =IF(케이스목록!$E8="","",케이스목록!$E8) -> 건담 게임용 카드 1묶음(50장), 건담 조립용 키트 3종, 설명서 2매(게임용·조립용)가 소매포장되어 제시된 물품. 카드에 표시된 공격력과 수비력을 비교해 승부를 내는 방식으로 게임을 진행함. 조립하여 완성한 미니어처 3종은 카드게임 규칙과 무관한 연출용. 업체 제시 가격비중은 카드 약 250엔, 조립키트 약 480엔 | D8: =IF(케이스목록!$D8="","",케이스목록!$D8) -> 9504400000 | E8: =IF(케이스목록!$H8="","",케이스목록!$H8) -> O | F8: X | G8: X | H8: 9504909000 | I8: =IF(OR($D8="",$H8=""),"",IF(LEFT(SUBSTITUTE(SUBSTITUTE(SUBSTITUTE(SUBSTITUTE(SUBSTITUTE($D8,".",""),"-","")," ","")," ",""),CHAR(9),""),4)=LEFT(SUBSTITUTE(SUBSTITUTE(SUBSTITUTE(SUBSTITUTE(SUBSTITUTE($H8,".",""),"-","")," ","")," ",""),CHAR(9),""),4),1,0)) -> 1 | J8: =IF(OR($D8="",$H8=""),"",IF(LEFT(SUBSTITUTE(SUBSTITUTE(SUBSTITUTE(SUBSTITUTE(SUBSTITUTE($D8,".",""),"-","")," ","")," ",""),CHAR(9),""),6)=LEFT(SUBSTITUTE(SUBSTITUTE(SUBSTITUTE(SUBSTITUTE(SUBSTITUTE($H8,".",""),"-","")," ","")," ",""),CHAR(9),""),6),1,0)) -> 0 | K8: =IF(OR($D8="",$H8=""),"",IF(SUBSTITUTE(SUBSTITUTE(SUBSTITUTE(SUBSTITUTE(SUBSTITUTE($D8,".",""),"-","")," ","")," ",""),CHAR(9),"")=SUBSTITUTE(SUBSTITUTE(SUBSTITUTE(SUBSTITUTE(SUBSTITUTE($H8,".",""),"-","")," ","")," ",""),CHAR(9),""),1,0)) -> 0 | L8: 9504909000 | M8: 9503003200 | N8: 9504400000 | O8: =IF(OR($D8="",$L8=""),"",IF(LEFT(SUBSTITUTE(SUBSTITUTE(SUBSTITUTE(SUBSTITUTE(SUBSTITUTE($D8,".",""),"-","")," ","")," ",""),CHAR(9),""),6)=LEFT(SUBSTITUTE(SUBSTITUTE(SUBSTITUTE(SUBSTITUTE(SUBSTITUTE($L8,".",""),"-","")," ","")," ",""),CHAR(9),""),6),1,0)) -> 0 | P8: =IF(OR($D8="",$L8=""),"",IF(OR(LEFT(SUBSTITUTE(SUBSTITUTE(SUBSTITUTE(SUBSTITUTE(SUBSTITUTE($D8,".",""),"-","")," ","")," ",""),CHAR(9),""),6)=LEFT(SUBSTITUTE(SUBSTITUTE(SUBSTITUTE(SUBSTITUTE(SUBSTITUTE($L8,".",""),"-","")," ","")," ",""),CHAR(9),""),6),LEFT(SUBSTITUTE(SUBSTITUTE(SUBSTITUTE(SUBSTITUTE(SUBSTITUTE($D8,".",""),"-","")," ","")," ",""),CHAR(9),""),6)=LEFT(SUBSTITUTE(SUBSTITUTE(SUBSTITUTE(SUBSTITUTE(SUBSTITUTE($M8,".",""),"-","")," ","")," ",""),CHAR(9),""),6),LEFT(SUBSTITUTE(SUBSTITUTE(SUBSTITUTE(SUBSTITUTE(SUBSTITUTE($D8,".",""),"-","")," ","")," ",""),CHAR(9),""),6)=LEFT(SUBSTITUTE(SUBSTITUTE(SUBSTITUTE(SUBSTITUTE(SUBSTITUTE($N8,".",""),"-","")," ","")," ",""),CHAR(9),""),6)),1,0)) -> 1 | Q8: 세트물품 통칙 적용 오류 | R8: 상세 설명의 조립키트 비중(480엔>250엔) 정보에 끌려 기타 오락용품으로 감. 조건B에서는 정답을 맞혔으므로 정보가 오히려 방해로 작용
A9: 5 | B9: =IF(케이스목록!$B9="","",케이스목록!$B9) -> 품목분류2과-31881 | C9: =IF(케이스목록!$E9="","",케이스목록!$E9) -> 아지드화나트륨(Sodium azide, CAS No. 26628-22-8) 0.1% 미만을 물에 용해한 무색투명한 액상을 플라스틱 용기에 소매포장한 것(내용량 3,300ml). 용도: 시험용 검체 주입 간 검체 바늘 및 컬럼 세척 등 | D9: =IF(케이스목록!$D9="","",케이스목록!$D9) -> 2850003000 | E9: =IF(케이스목록!$H9="","",케이스목록!$H9) -> O | F9: X | G9: X | H9: 3822199000 | I9: =IF(OR($D9="",$H9=""),"",IF(LEFT(SUBSTITUTE(SUBSTITUTE(SUBSTITUTE(SUBSTITUTE(SUBSTITUTE($D9,".",""),"-","")," ","")," ",""),CHAR(9),""),4)=LEFT(SUBSTITUTE(SUBSTITUTE(SUBSTITUTE(SUBSTITUTE(SUBSTITUTE($H9,".",""),"-","")," ","")," ",""),CHAR(9),""),4),1,0)) -> 0 | J9: =IF(OR($D9="",$H9=""),"",IF(LEFT(SUBSTITUTE(SUBSTITUTE(SUBSTITUTE(SUBSTITUTE(SUBSTITUTE($D9,".",""),"-","")," ","")," ",""),CHAR(9),""),6)=LEFT(SUBSTITUTE(SUBSTITUTE(SUBSTITUTE(SUBSTITUTE(SUBSTITUTE($H9,".",""),"-","")," ","")," ",""),CHAR(9),""),6),1,0)) -> 0 | K9: =IF(OR($D9="",$H9=""),"",IF(SUBSTITUTE(SUBSTITUTE(SUBSTITUTE(SUBSTITUTE(SUBSTITUTE($D9,".",""),"-","")," ","")," ",""),CHAR(9),"")=SUBSTITUTE(SUBSTITUTE(SUBSTITUTE(SUBSTITUTE(SUBSTITUTE($H9,".",""),"-","")," ","")," ",""),CHAR(9),""),1,0)) -> 0 | L9: 3822199000 | M9: 2850001000 | N9: 3824999090 | O9: =IF(OR($D9="",$L9=""),"",IF(LEFT(SUBSTITUTE(SUBSTITUTE(SUBSTITUTE(SUBSTITUTE(SUBSTITUTE($D9,".",""),"-","")," ","")," ",""),CHAR(9),""),6)=LEFT(SUBSTITUTE(SUBSTITUTE(SUBSTITUTE(SUBSTITUTE(SUBSTITUTE($L9,".",""),"-","")," ","")," ",""),CHAR(9),""),6),1,0)) -> 0 | P9: =IF(OR($D9="",$L9=""),"",IF(OR(LEFT(SUBSTITUTE(SUBSTITUTE(SUBSTITUTE(SUBSTITUTE(SUBSTITUTE($D9,".",""),"-","")," ","")," ",""),CHAR(9),""),6)=LEFT(SUBSTITUTE(SUBSTITUTE(SUBSTITUTE(SUBSTITUTE(SUBSTITUTE($L9,".",""),"-","")," ","")," ",""),CHAR(9),""),6),LEFT(SUBSTITUTE(SUBSTITUTE(SUBSTITUTE(SUBSTITUTE(SUBSTITUTE($D9,".",""),"-","")," ","")," ",""),CHAR(9),""),6)=LEFT(SUBSTITUTE(SUBSTITUTE(SUBSTITUTE(SUBSTITUTE(SUBSTITUTE($M9,".",""),"-","")," ","")," ",""),CHAR(9),""),6),LEFT(SUBSTITUTE(SUBSTITUTE(SUBSTITUTE(SUBSTITUTE(SUBSTITUTE($D9,".",""),"-","")," ","")," ",""),CHAR(9),""),6)=LEFT(SUBSTITUTE(SUBSTITUTE(SUBSTITUTE(SUBSTITUTE(SUBSTITUTE($N9,".",""),"-","")," ","")," ",""),CHAR(9),""),6)),1,0)) -> 1 | Q9: 호 경합 판단 오류 | R9: 수용액이라는 이유로 단일 화합물이 아니라 보고 곧바로 38류 시약으로 감. 28류 주 제1호의 용매 용해 허용 규정을 적용하지 못함
A10: 6 | B10: =IF(케이스목록!$B10="","",케이스목록!$B10) -> 품목분류3과-3310 | C10: =IF(케이스목록!$E10="","",케이스목록!$E10) -> ㅇ 실리콘(Silicone) 재질의 호스 또는 PTFE(Polytetrafluoroethylene) 재질의 호스로서, 양 끝단에는 스테인리스 스틸 연결구가 부착됨 - (용도) 유체 이송(배지, 약액, 최종원액 등)용으로 제약(백신) 제조공정*의 여러 장비**에 연결되어 사용됨 * 세포에서 항체를 만들고, 불순물과 바이러스를 제거한 뒤 농축‧조성 조정을 거쳐 최종 용기에 무균 충전하는 공정 ** Chromatography skid, Virus filter skid, UF/DF skid, Filling station ㅇ SXW : 약 길이 1200㎜, 직경 48㎜, 파열압 0.345 ∼ 1.03(㎫), 실리콘재질, 스테인리스 스틸 와이어로 보강됨 ※ 제조사 홈페이지: “의약품, 화장품 및 식품이송에 적합” | D10: =IF(케이스목록!$D10="","",케이스목록!$D10) -> 3917399000 | E10: =IF(케이스목록!$H10="","",케이스목록!$H10) -> O | F10: X | G10: X | H10: 3917.39-9000 | I10: =IF(OR($D10="",$H10=""),"",IF(LEFT(SUBSTITUTE(SUBSTITUTE(SUBSTITUTE(SUBSTITUTE(SUBSTITUTE($D10,".",""),"-","")," ","")," ",""),CHAR(9),""),4)=LEFT(SUBSTITUTE(SUBSTITUTE(SUBSTITUTE(SUBSTITUTE(SUBSTITUTE($H10,".",""),"-","")," ","")," ",""),CHAR(9),""),4),1,0)) -> 1 | J10: =IF(OR($D10="",$H10=""),"",IF(LEFT(SUBSTITUTE(SUBSTITUTE(SUBSTITUTE(SUBSTITUTE(SUBSTITUTE($D10,".",""),"-","")," ","")," ",""),CHAR(9),""),6)=LEFT(SUBSTITUTE(SUBSTITUTE(SUBSTITUTE(SUBSTITUTE(SUBSTITUTE($H10,".",""),"-","")," ","")," ",""),CHAR(9),""),6),1,0)) -> 1 | K10: =IF(OR($D10="",$H10=""),"",IF(SUBSTITUTE(SUBSTITUTE(SUBSTITUTE(SUBSTITUTE(SUBSTITUTE($D10,".",""),"-","")," ","")," ",""),CHAR(9),"")=SUBSTITUTE(SUBSTITUTE(SUBSTITUTE(SUBSTITUTE(SUBSTITUTE($H10,".",""),"-","")," ","")," ",""),CHAR(9),""),1,0)) -> 1 | L10: 3917.39-9000 | M10: 3917.33-9000 | N10: 8421.99-9090 | O10: =IF(OR($D10="",$L10=""),"",IF(LEFT(SUBSTITUTE(SUBSTITUTE(SUBSTITUTE(SUBSTITUTE(SUBSTITUTE($D10,".",""),"-","")," ","")," ",""),CHAR(9),""),6)=LEFT(SUBSTITUTE(SUBSTITUTE(SUBSTITUTE(SUBSTITUTE(SUBSTITUTE($L10,".",""),"-","")," ","")," ",""),CHAR(9),""),6),1,0)) -> 1 | P10: =IF(OR($D10="",$L10=""),"",IF(OR(LEFT(SUBSTITUTE(SUBSTITUTE(SUBSTITUTE(SUBSTITUTE(SUBSTITUTE($D10,".",""),"-","")," ","")," ",""),CHAR(9),""),6)=LEFT(SUBSTITUTE(SUBSTITUTE(SUBSTITUTE(SUBSTITUTE(SUBSTITUTE($L10,".",""),"-","")," ","")," ",""),CHAR(9),""),6),LEFT(SUBSTITUTE(SUBSTITUTE(SUBSTITUTE(SUBSTITUTE(SUBSTITUTE($D10,".",""),"-","")," ","")," ",""),CHAR(9),""),6)=LEFT(SUBSTITUTE(SUBSTITUTE(SUBSTITUTE(SUBSTITUTE(SUBSTITUTE($M10,".",""),"-","")," ","")," ",""),CHAR(9),""),6),LEFT(SUBSTITUTE(SUBSTITUTE(SUBSTITUTE(SUBSTITUTE(SUBSTITUTE($D10,".",""),"-","")," ","")," ",""),CHAR(9),""),6)=LEFT(SUBSTITUTE(SUBSTITUTE(SUBSTITUTE(SUBSTITUTE(SUBSTITUTE($N10,".",""),"-","")," ","")," ",""),CHAR(9),""),6)),1,0)) -> 1
A11: 7 | B11: =IF(케이스목록!$B11="","",케이스목록!$B11) -> 품목분류3과-3040 | C11: =IF(케이스목록!$E11="","",케이스목록!$E11) -> ㅇ 물품개요 - 화장품 CUSHION COMPACT 용기를 구성하는 ① 외용기, ② 내용기, ③ 매쉬링(리드씰 포함)이 미조립 상태로 제시, 각 구성요소를 결합하면 케이스 완성품이 됨 (파운데이션 내용물 미포함) - 구성요소는 각 개별박스에 벌크 포장된 형태로 함께 제시 - 구성요소 ① 외용기(ABS, AS, GLASS) : 내부에 거울이 부착된 화장품 외부 용기 ② 내용기(PP) : 화장품(파운데이션)을 담는 내부 용기 ③ 매쉬링(리드씰 포함)(NYLON, PP/PE, AL) : 화장품이 균일하게 도포되도록 돕는 매쉬망과 고정링에 제품보호용 씰(제거후 사용)이 부착됨 ㅇ 수입 후 제조공정 - 원료 칭량(Weighing) → 교반 → 믹싱 → 내용기 충전(몰드진입, 용기공급, 충전, 매쉬망, 실링, 라벨링, 배출) → 외용기 결합 → 포장 | D11: =IF(케이스목록!$D11="","",케이스목록!$D11) -> 3923100000 | E11: =IF(케이스목록!$H11="","",케이스목록!$H11) -> O | F11: X | G11: X | H11: 3923.90-0000 | I11: =IF(OR($D11="",$H11=""),"",IF(LEFT(SUBSTITUTE(SUBSTITUTE(SUBSTITUTE(SUBSTITUTE(SUBSTITUTE($D11,".",""),"-","")," ","")," ",""),CHAR(9),""),4)=LEFT(SUBSTITUTE(SUBSTITUTE(SUBSTITUTE(SUBSTITUTE(SUBSTITUTE($H11,".",""),"-","")," ","")," ",""),CHAR(9),""),4),1,0)) -> 1 | J11: =IF(OR($D11="",$H11=""),"",IF(LEFT(SUBSTITUTE(SUBSTITUTE(SUBSTITUTE(SUBSTITUTE(SUBSTITUTE($D11,".",""),"-","")," ","")," ",""),CHAR(9),""),6)=LEFT(SUBSTITUTE(SUBSTITUTE(SUBSTITUTE(SUBSTITUTE(SUBSTITUTE($H11,".",""),"-","")," ","")," ",""),CHAR(9),""),6),1,0)) -> 0 | K11: =IF(OR($D11="",$H11=""),"",IF(SUBSTITUTE(SUBSTITUTE(SUBSTITUTE(SUBSTITUTE(SUBSTITUTE($D11,".",""),"-","")," ","")," ",""),CHAR(9),"")=SUBSTITUTE(SUBSTITUTE(SUBSTITUTE(SUBSTITUTE(SUBSTITUTE($H11,".",""),"-","")," ","")," ",""),CHAR(9),""),1,0)) -> 0 | L11: 3923.90-0000 | M11: 3926.90-9000 | N11: 3923.30-0000 | O11: =IF(OR($D11="",$L11=""),"",IF(LEFT(SUBSTITUTE(SUBSTITUTE(SUBSTITUTE(SUBSTITUTE(SUBSTITUTE($D11,".",""),"-","")," ","")," ",""),CHAR(9),""),6)=LEFT(SUBSTITUTE(SUBSTITUTE(SUBSTITUTE(SUBSTITUTE(SUBSTITUTE($L11,".",""),"-","")," ","")," ",""),CHAR(9),""),6),1,0)) -> 0 | P11: =IF(OR($D11="",$L11=""),"",IF(OR(LEFT(SUBSTITUTE(SUBSTITUTE(SUBSTITUTE(SUBSTITUTE(SUBSTITUTE($D11,".",""),"-","")," ","")," ",""),CHAR(9),""),6)=LEFT(SUBSTITUTE(SUBSTITUTE(SUBSTITUTE(SUBSTITUTE(SUBSTITUTE($L11,".",""),"-","")," ","")," ",""),CHAR(9),""),6),LEFT(SUBSTITUTE(SUBSTITUTE(SUBSTITUTE(SUBSTITUTE(SUBSTITUTE($D11,".",""),"-","")," ","")," ",""),CHAR(9),""),6)=LEFT(SUBSTITUTE(SUBSTITUTE(SUBSTITUTE(SUBSTITUTE(SUBSTITUTE($M11,".",""),"-","")," ","")," ",""),CHAR(9),""),6),LEFT(SUBSTITUTE(SUBSTITUTE(SUBSTITUTE(SUBSTITUTE(SUBSTITUTE($D11,".",""),"-","")," ","")," ",""),CHAR(9),""),6)=LEFT(SUBSTITUTE(SUBSTITUTE(SUBSTITUTE(SUBSTITUTE(SUBSTITUTE($N11,".",""),"-","")," ","")," ",""),CHAR(9),""),6)),1,0)) -> 0 | Q11: 세트물품 통칙 적용 오류
A12: 8 | B12: =IF(케이스목록!$B12="","",케이스목록!$B12) -> 품목분류4과-1253 | C12: =IF(케이스목록!$E12="","",케이스목록!$E12) -> ㅇ (개요) ① Polyurethane acrylate*(우레탄계 프리폴리머) 35~40%, ② 2-Propenoic acid reaction products with pentaerythritol(미반응원료) 10~15%, ③ Ethoxylated pentaerythritol tetraacrylate(점도조정제, 희석제) 50%로 구성된 무색투명한 점조액상 * 성분명 : 2-[[(1-Oxo-2-propenyl)oxy]methyl]-2-[[[[[[1,3,3-trimethyl-5- [[[3-[(1-oxo-2-propenyl)oxy]-2,2-bis[[(1-oxo-2-propenyl)oxy]methyl]propoxy]carbonyl]amino]cyclohexyl]methyl]amino]carbonyl]oxy]methyl]-1,3-propanediyl 2-propenoate ㅇ (제조공정) 원료 투입 → 반응 → 여과 및 포장 ㅇ (원료) | D12: =IF(케이스목록!$D12="","",케이스목록!$D12) -> 3909500000 | E12: =IF(케이스목록!$H12="","",케이스목록!$H12) -> O | F12: X | G12: X | H12: 3909.50-0000 | I12: =IF(OR($D12="",$H12=""),"",IF(LEFT(SUBSTITUTE(SUBSTITUTE(SUBSTITUTE(SUBSTITUTE(SUBSTITUTE($D12,".",""),"-","")," ","")," ",""),CHAR(9),""),4)=LEFT(SUBSTITUTE(SUBSTITUTE(SUBSTITUTE(SUBSTITUTE(SUBSTITUTE($H12,".",""),"-","")," ","")," ",""),CHAR(9),""),4),1,0)) -> 1 | J12: =IF(OR($D12="",$H12=""),"",IF(LEFT(SUBSTITUTE(SUBSTITUTE(SUBSTITUTE(SUBSTITUTE(SUBSTITUTE($D12,".",""),"-","")," ","")," ",""),CHAR(9),""),6)=LEFT(SUBSTITUTE(SUBSTITUTE(SUBSTITUTE(SUBSTITUTE(SUBSTITUTE($H12,".",""),"-","")," ","")," ",""),CHAR(9),""),6),1,0)) -> 1 | K12: =IF(OR($D12="",$H12=""),"",IF(SUBSTITUTE(SUBSTITUTE(SUBSTITUTE(SUBSTITUTE(SUBSTITUTE($D12,".",""),"-","")," ","")," ",""),CHAR(9),"")=SUBSTITUTE(SUBSTITUTE(SUBSTITUTE(SUBSTITUTE(SUBSTITUTE($H12,".",""),"-","")," ","")," ",""),CHAR(9),""),1,0)) -> 1 | L12: 3909.50-0000 | M12: 3906.90-9000 | N12: 3824.99-9090 | O12: =IF(OR($D12="",$L12=""),"",IF(LEFT(SUBSTITUTE(SUBSTITUTE(SUBSTITUTE(SUBSTITUTE(SUBSTITUTE($D12,".",""),"-","")," ","")," ",""),CHAR(9),""),6)=LEFT(SUBSTITUTE(SUBSTITUTE(SUBSTITUTE(SUBSTITUTE(SUBSTITUTE($L12,".",""),"-","")," ","")," ",""),CHAR(9),""),6),1,0)) -> 1 | P12: =IF(OR($D12="",$L12=""),"",IF(OR(LEFT(SUBSTITUTE(SUBSTITUTE(SUBSTITUTE(SUBSTITUTE(SUBSTITUTE($D12,".",""),"-","")," ","")," ",""),CHAR(9),""),6)=LEFT(SUBSTITUTE(SUBSTITUTE(SUBSTITUTE(SUBSTITUTE(SUBSTITUTE($L12,".",""),"-","")," ","")," ",""),CHAR(9),""),6),LEFT(SUBSTITUTE(SUBSTITUTE(SUBSTITUTE(SUBSTITUTE(SUBSTITUTE($D12,".",""),"-","")," ","")," ",""),CHAR(9),""),6)=LEFT(SUBSTITUTE(SUBSTITUTE(SUBSTITUTE(SUBSTITUTE(SUBSTITUTE($M12,".",""),"-","")," ","")," ",""),CHAR(9),""),6),LEFT(SUBSTITUTE(SUBSTITUTE(SUBSTITUTE(SUBSTITUTE(SUBSTITUTE($D12,".",""),"-","")," ","")," ",""),CHAR(9),""),6)=LEFT(SUBSTITUTE(SUBSTITUTE(SUBSTITUTE(SUBSTITUTE(SUBSTITUTE($N12,".",""),"-","")," ","")," ",""),CHAR(9),""),6)),1,0)) -> 1
A13: 9 | B13: =IF(케이스목록!$B13="","",케이스목록!$B13) -> 품목분류4과-1933 | C13: =IF(케이스목록!$E13="","",케이스목록!$E13) -> ㅇ 물품개요 - 안건 물품은 선박의 기관실 등에서 화재 발생시 화재감지 신호에 따라 펌프가 작동하여 물을 미립화하여 고압으로 분무함으로써 화재를 진압하는 화재 진압 시스템(소화수 탱크는 미제시됨) ㅇ 용도 : 선박 기관실(주기관, 발전기, 보일러 등 고위험 설비)내의 화재 방호 ㅇ 작동원리 : 물 입자를 미분무수화하여 표면적을 증가시키고 열을 흡수함과 동시에 물의 증발을 최대화하여 냉각 효과로 소화 ㅇ 주요 구성요소 및 기능 - 펌프 : 화재 발생시 노즐로 소화수를 전달 - 컨트롤판넬 : 시스템 제어 및 상태관리 - 미분수 노즐 : 소화수(물)를 분사하여 화재를 진압하는 장치 - 배관 및 밸브 : 제어 신호에 따라 소화수 공급 및 배관 라인 개폐 - 화재감지기 : 화재 발생시 연기, 열, 화염 등을 감지하여 컨트롤판넬로 전달 - (미제시) 소화수 탱크 : 소화수를 저장하는 장치이며 펌프와 배관으로 연결 | D13: =IF(케이스목록!$D13="","",케이스목록!$D13) -> 8424899000 | E13: =IF(케이스목록!$H13="","",케이스목록!$H13) -> O | F13: X | G13: X | H13: 8424.89-9000 | I13: =IF(OR($D13="",$H13=""),"",IF(LEFT(SUBSTITUTE(SUBSTITUTE(SUBSTITUTE(SUBSTITUTE(SUBSTITUTE($D13,".",""),"-","")," ","")," ",""),CHAR(9),""),4)=LEFT(SUBSTITUTE(SUBSTITUTE(SUBSTITUTE(SUBSTITUTE(SUBSTITUTE($H13,".",""),"-","")," ","")," ",""),CHAR(9),""),4),1,0)) -> 1 | J13: =IF(OR($D13="",$H13=""),"",IF(LEFT(SUBSTITUTE(SUBSTITUTE(SUBSTITUTE(SUBSTITUTE(SUBSTITUTE($D13,".",""),"-","")," ","")," ",""),CHAR(9),""),6)=LEFT(SUBSTITUTE(SUBSTITUTE(SUBSTITUTE(SUBSTITUTE(SUBSTITUTE($H13,".",""),"-","")," ","")," ",""),CHAR(9),""),6),1,0)) -> 1 | K13: =IF(OR($D13="",$H13=""),"",IF(SUBSTITUTE(SUBSTITUTE(SUBSTITUTE(SUBSTITUTE(SUBSTITUTE($D13,".",""),"-","")," ","")," ",""),CHAR(9),"")=SUBSTITUTE(SUBSTITUTE(SUBSTITUTE(SUBSTITUTE(SUBSTITUTE($H13,".",""),"-","")," ","")," ",""),CHAR(9),""),1,0)) -> 1 | L13: 8424.89-9000 | M13: 8424.10-0000 | N13: 8424.90-9000 | O13: =IF(OR($D13="",$L13=""),"",IF(LEFT(SUBSTITUTE(SUBSTITUTE(SUBSTITUTE(SUBSTITUTE(SUBSTITUTE($D13,".",""),"-","")," ","")," ",""),CHAR(9),""),6)=LEFT(SUBSTITUTE(SUBSTITUTE(SUBSTITUTE(SUBSTITUTE(SUBSTITUTE($L13,".",""),"-","")," ","")," ",""),CHAR(9),""),6),1,0)) -> 1 | P13: =IF(OR($D13="",$L13=""),"",IF(OR(LEFT(SUBSTITUTE(SUBSTITUTE(SUBSTITUTE(SUBSTITUTE(SUBSTITUTE($D13,".",""),"-","")," ","")," ",""),CHAR(9),""),6)=LEFT(SUBSTITUTE(SUBSTITUTE(SUBSTITUTE(SUBSTITUTE(SUBSTITUTE($L13,".",""),"-","")," ","")," ",""),CHAR(9),""),6),LEFT(SUBSTITUTE(SUBSTITUTE(SUBSTITUTE(SUBSTITUTE(SUBSTITUTE($D13,".",""),"-","")," ","")," ",""),CHAR(9),""),6)=LEFT(SUBSTITUTE(SUBSTITUTE(SUBSTITUTE(SUBSTITUTE(SUBSTITUTE($M13,".",""),"-","")," ","")," ",""),CHAR(9),""),6),LEFT(SUBSTITUTE(SUBSTITUTE(SUBSTITUTE(SUBSTITUTE(SUBSTITUTE($D13,".",""),"-","")," ","")," ",""),CHAR(9),""),6)=LEFT(SUBSTITUTE(SUBSTITUTE(SUBSTITUTE(SUBSTITUTE(SUBSTITUTE($N13,".",""),"-","")," ","")," ",""),CHAR(9),""),6)),1,0)) -> 1
A14: 10 | B14: =IF(케이스목록!$B14="","",케이스목록!$B14) -> 품목분류3과-3871 | C14: =IF(케이스목록!$E14="","",케이스목록!$E14) -> ㅇ 물품 개요 - 반도체 세정장비*(SU-3200)에 사용되는 산업용 컴퓨터로 제어 프로그램이 설치되어 수입 * 반도체 제조공정 중 발생한 Wafer 표면의 각종 이물질을 화공약품을 이용하여 제거 ㅇ 기능 및 용도: 장비 전체 운영의 중앙 제어, 장비 상태 모니터링 및 보호, 데이터 수집 및 로깅, 장비 최적화·스케줄링 기능, 보안·사용자 권한 관리, 서브 시스템과의 통신 및 제어 명령 분배 ㅇ 일반 프로그램 설치 가능 여부 - 신청 물품은 Windows 운영체제가 설치된 산업용 컴퓨터로서, 일반 PC와 동일하게 다양한 프로그램의 설치 및 실행이 가능하며, 프로그램 설치와 관련된 기술적 제한 없음 ㅇ 제어 방식: 신청 물품이 장치 운용을 위한 명령*을 VME Controller에 지시 → VME Controller는 다시 각 모듈**에 동작***을 지시 → 모듈 수행에 따른 각종 데이터를 다시 VME Controller가 취합 후 신청 물품으로 송부 * 사용자 입력 및 시스템 조건에 따른 장비의 가동, 정지, 중단 ** 로봇 컨트톨러, 반송 장치, 챔버, 밸브, 센서 등 *** 로봇 동작(Move, Pick up, Place 등), Motor/Pump 제어(위치, 속도 관련 정보) 등 | D14: =IF(케이스목록!$D14="","",케이스목록!$D14) -> 8471501000 | E14: =IF(케이스목록!$H14="","",케이스목록!$H14) -> O | F14: X | G14: X | H14: 8471.50-9000 | I14: =IF(OR($D14="",$H14=""),"",IF(LEFT(SUBSTITUTE(SUBSTITUTE(SUBSTITUTE(SUBSTITUTE(SUBSTITUTE($D14,".",""),"-","")," ","")," ",""),CHAR(9),""),4)=LEFT(SUBSTITUTE(SUBSTITUTE(SUBSTITUTE(SUBSTITUTE(SUBSTITUTE($H14,".",""),"-","")," ","")," ",""),CHAR(9),""),4),1,0)) -> 1 | J14: =IF(OR($D14="",$H14=""),"",IF(LEFT(SUBSTITUTE(SUBSTITUTE(SUBSTITUTE(SUBSTITUTE(SUBSTITUTE($D14,".",""),"-","")," ","")," ",""),CHAR(9),""),6)=LEFT(SUBSTITUTE(SUBSTITUTE(SUBSTITUTE(SUBSTITUTE(SUBSTITUTE($H14,".",""),"-","")," ","")," ",""),CHAR(9),""),6),1,0)) -> 1 | K14: =IF(OR($D14="",$H14=""),"",IF(SUBSTITUTE(SUBSTITUTE(SUBSTITUTE(SUBSTITUTE(SUBSTITUTE($D14,".",""),"-","")," ","")," ",""),CHAR(9),"")=SUBSTITUTE(SUBSTITUTE(SUBSTITUTE(SUBSTITUTE(SUBSTITUTE($H14,".",""),"-","")," ","")," ",""),CHAR(9),""),1,0)) -> 0 | L14: 8471.50-9000 | M14: 8486.90-3020 | N14: 8537.10-9000 | O14: =IF(OR($D14="",$L14=""),"",IF(LEFT(SUBSTITUTE(SUBSTITUTE(SUBSTITUTE(SUBSTITUTE(SUBSTITUTE($D14,".",""),"-","")," ","")," ",""),CHAR(9),""),6)=LEFT(SUBSTITUTE(SUBSTITUTE(SUBSTITUTE(SUBSTITUTE(SUBSTITUTE($L14,".",""),"-","")," ","")," ",""),CHAR(9),""),6),1,0)) -> 1 | P14: =IF(OR($D14="",$L14=""),"",IF(OR(LEFT(SUBSTITUTE(SUBSTITUTE(SUBSTITUTE(SUBSTITUTE(SUBSTITUTE($D14,".",""),"-","")," ","")," ",""),CHAR(9),""),6)=LEFT(SUBSTITUTE(SUBSTITUTE(SUBSTITUTE(SUBSTITUTE(SUBSTITUTE($L14,".",""),"-","")," ","")," ",""),CHAR(9),""),6),LEFT(SUBSTITUTE(SUBSTITUTE(SUBSTITUTE(SUBSTITUTE(SUBSTITUTE($D14,".",""),"-","")," ","")," ",""),CHAR(9),""),6)=LEFT(SUBSTITUTE(SUBSTITUTE(SUBSTITUTE(SUBSTITUTE(SUBSTITUTE($M14,".",""),"-","")," ","")," ",""),CHAR(9),""),6),LEFT(SUBSTITUTE(SUBSTITUTE(SUBSTITUTE(SUBSTITUTE(SUBSTITUTE($D14,".",""),"-","")," ","")," ",""),CHAR(9),""),6)=LEFT(SUBSTITUTE(SUBSTITUTE(SUBSTITUTE(SUBSTITUTE(SUBSTITUTE($N14,".",""),"-","")," ","")," ",""),CHAR(9),""),6)),1,0)) -> 1 | Q14: 한국 고유 세번(10자리) 오류
A15: 11 | B15: =IF(케이스목록!$B15="","",케이스목록!$B15) -> 품목분류2과-1654 | C15: =IF(케이스목록!$E15="","",케이스목록!$E15) -> ㅇ 물품개요 - 수소처리된 경질 나프타[Naphtha(petroleum), hydrotreated light] (85%~95%), 방향족 탄화수소 혼합물* (1%~10%)을 혼합한 무색 투명한 액상[비방향족 성분 중량이 방향족 성분 중량을 초과, ISO 3405방법으로 210℃에서 90%이상 증류] * Mixed xylene : 에틸벤젠(Ethylbenzene) 50~60%, 크실렌(Xylene) 40~50% - 용도: 산업용 용제 | D15: =IF(케이스목록!$D15="","",케이스목록!$D15) -> 2710129000 | E15: =IF(케이스목록!$H15="","",케이스목록!$H15) -> O | F15: X | G15: X | H15: 2710.12-4000 | I15: =IF(OR($D15="",$H15=""),"",IF(LEFT(SUBSTITUTE(SUBSTITUTE(SUBSTITUTE(SUBSTITUTE(SUBSTITUTE($D15,".",""),"-","")," ","")," ",""),CHAR(9),""),4)=LEFT(SUBSTITUTE(SUBSTITUTE(SUBSTITUTE(SUBSTITUTE(SUBSTITUTE($H15,".",""),"-","")," ","")," ",""),CHAR(9),""),4),1,0)) -> 1 | J15: =IF(OR($D15="",$H15=""),"",IF(LEFT(SUBSTITUTE(SUBSTITUTE(SUBSTITUTE(SUBSTITUTE(SUBSTITUTE($D15,".",""),"-","")," ","")," ",""),CHAR(9),""),6)=LEFT(SUBSTITUTE(SUBSTITUTE(SUBSTITUTE(SUBSTITUTE(SUBSTITUTE($H15,".",""),"-","")," ","")," ",""),CHAR(9),""),6),1,0)) -> 1 | K15: =IF(OR($D15="",$H15=""),"",IF(SUBSTITUTE(SUBSTITUTE(SUBSTITUTE(SUBSTITUTE(SUBSTITUTE($D15,".",""),"-","")," ","")," ",""),CHAR(9),"")=SUBSTITUTE(SUBSTITUTE(SUBSTITUTE(SUBSTITUTE(SUBSTITUTE($H15,".",""),"-","")," ","")," ",""),CHAR(9),""),1,0)) -> 0 | L15: 2710.12-4000 | M15: 2710.12-3000 | N15: 2710.12-9000 | O15: =IF(OR($D15="",$L15=""),"",IF(LEFT(SUBSTITUTE(SUBSTITUTE(SUBSTITUTE(SUBSTITUTE(SUBSTITUTE($D15,".",""),"-","")," ","")," ",""),CHAR(9),""),6)=LEFT(SUBSTITUTE(SUBSTITUTE(SUBSTITUTE(SUBSTITUTE(SUBSTITUTE($L15,".",""),"-","")," ","")," ",""),CHAR(9),""),6),1,0)) -> 1 | P15: =IF(OR($D15="",$L15=""),"",IF(OR(LEFT(SUBSTITUTE(SUBSTITUTE(SUBSTITUTE(SUBSTITUTE(SUBSTITUTE($D15,".",""),"-","")," ","")," ",""),CHAR(9),""),6)=LEFT(SUBSTITUTE(SUBSTITUTE(SUBSTITUTE(SUBSTITUTE(SUBSTITUTE($L15,".",""),"-","")," ","")," ",""),CHAR(9),""),6),LEFT(SUBSTITUTE(SUBSTITUTE(SUBSTITUTE(SUBSTITUTE(SUBSTITUTE($D15,".",""),"-","")," ","")," ",""),CHAR(9),""),6)=LEFT(SUBSTITUTE(SUBSTITUTE(SUBSTITUTE(SUBSTITUTE(SUBSTITUTE($M15,".",""),"-","")," ","")," ",""),CHAR(9),""),6),LEFT(SUBSTITUTE(SUBSTITUTE(SUBSTITUTE(SUBSTITUTE(SUBSTITUTE($D15,".",""),"-","")," ","")," ",""),CHAR(9),""),6)=LEFT(SUBSTITUTE(SUBSTITUTE(SUBSTITUTE(SUBSTITUTE(SUBSTITUTE($N15,".",""),"-","")," ","")," ",""),CHAR(9),""),6)),1,0)) -> 1
A16: 12 | B16: =IF(케이스목록!$B16="","",케이스목록!$B16) -> 품목분류2과-1460 | C16: =IF(케이스목록!$E16="","",케이스목록!$E16) -> ㅇ 물품개요 - 원상의 생강을 끓는 물에 담가 세척하고 절단하여 설탕 시럽(끓는 물에 설탕을 녹여 만든 시럽을 용기 3개에 담은 후 순차적으로 침적)에 침적한 후 잔류 시럽을 배출한 생강 채 50%에 설탕 50%를 넣어 포장하여 냉동한 것 - 용도 : 식용(생강차 제조용) - 분석결과 ▪시료 : 수분 약 36.9% ①자당 약 56% ②자당 약 50% / 시럽 자당 약 59% ▪생강(미 농무성) : 수분 78.9%, 당 1.7% - 제조공정 원상의 생강 ⇒ 세척(끓는 물에 담금/살균 및 전분 제거) ⇒ 채 썰기 ⇒ 설탕 시럽에 3회 침적(끓는 물에 설탕을 녹여 만든 시럽을 용기* 3개에 나눠 담은 후 생강 채를 각 시럽에 순차적으로 침적) ⇒ 시럽 배출 ⇒ 설탕 혼합 ⇒ 포장 ⇒ 냉동 ※ 생강 채를 시럽에 넣어 끓이지 않는 이유 - 생강 채를 설탕 시럽에 담근 상태에서 끓이면 생강의 형태를 유지하기 어렵기 때문에, 생강 형상을 최대한 유지하기 위해 끓는 물에 설탕을 녹여 만든 시럽에 침적하는 방식으로 제조 | D16: =IF(케이스목록!$D16="","",케이스목록!$D16) -> 2008999000 | E16: =IF(케이스목록!$H16="","",케이스목록!$H16) -> O | F16: X | G16: X | H16: 2006.00-9000 | I16: =IF(OR($D16="",$H16=""),"",IF(LEFT(SUBSTITUTE(SUBSTITUTE(SUBSTITUTE(SUBSTITUTE(SUBSTITUTE($D16,".",""),"-","")," ","")," ",""),CHAR(9),""),4)=LEFT(SUBSTITUTE(SUBSTITUTE(SUBSTITUTE(SUBSTITUTE(SUBSTITUTE($H16,".",""),"-","")," ","")," ",""),CHAR(9),""),4),1,0)) -> 0 | J16: =IF(OR($D16="",$H16=""),"",IF(LEFT(SUBSTITUTE(SUBSTITUTE(SUBSTITUTE(SUBSTITUTE(SUBSTITUTE($D16,".",""),"-","")," ","")," ",""),CHAR(9),""),6)=LEFT(SUBSTITUTE(SUBSTITUTE(SUBSTITUTE(SUBSTITUTE(SUBSTITUTE($H16,".",""),"-","")," ","")," ",""),CHAR(9),""),6),1,0)) -> 0 | K16: =IF(OR($D16="",$H16=""),"",IF(SUBSTITUTE(SUBSTITUTE(SUBSTITUTE(SUBSTITUTE(SUBSTITUTE($D16,".",""),"-","")," ","")," ",""),CHAR(9),"")=SUBSTITUTE(SUBSTITUTE(SUBSTITUTE(SUBSTITUTE(SUBSTITUTE($H16,".",""),"-","")," ","")," ",""),CHAR(9),""),1,0)) -> 0 | L16: 2006.00-9000 | M16: 2008.99-9000 | N16: 2106.90-9099 | O16: =IF(OR($D16="",$L16=""),"",IF(LEFT(SUBSTITUTE(SUBSTITUTE(SUBSTITUTE(SUBSTITUTE(SUBSTITUTE($D16,".",""),"-","")," ","")," ",""),CHAR(9),""),6)=LEFT(SUBSTITUTE(SUBSTITUTE(SUBSTITUTE(SUBSTITUTE(SUBSTITUTE($L16,".",""),"-","")," ","")," ",""),CHAR(9),""),6),1,0)) -> 0 | P16: =IF(OR($D16="",$L16=""),"",IF(OR(LEFT(SUBSTITUTE(SUBSTITUTE(SUBSTITUTE(SUBSTITUTE(SUBSTITUTE($D16,".",""),"-","")," ","")," ",""),CHAR(9),""),6)=LEFT(SUBSTITUTE(SUBSTITUTE(SUBSTITUTE(SUBSTITUTE(SUBSTITUTE($L16,".",""),"-","")," ","")," ",""),CHAR(9),""),6),LEFT(SUBSTITUTE(SUBSTITUTE(SUBSTITUTE(SUBSTITUTE(SUBSTITUTE($D16,".",""),"-","")," ","")," ",""),CHAR(9),""),6)=LEFT(SUBSTITUTE(SUBSTITUTE(SUBSTITUTE(SUBSTITUTE(SUBSTITUTE($M16,".",""),"-","")," ","")," ",""),CHAR(9),""),6),LEFT(SUBSTITUTE(SUBSTITUTE(SUBSTITUTE(SUBSTITUTE(SUBSTITUTE($D16,".",""),"-","")," ","")," ",""),CHAR(9),""),6)=LEFT(SUBSTITUTE(SUBSTITUTE(SUBSTITUTE(SUBSTITUTE(SUBSTITUTE($N16,".",""),"-","")," ","")," ",""),CHAR(9),""),6)),1,0)) -> 1 | Q16: 용도/기능 오인 | R16: ‘설탕으로 보존처리한 과실’에서도 “과실을 설탕시럽에 넣어 설탕이 충분히 스며들도록 비등점까지 가열하여 당 농도가 증가하도록 보존처리한 것일 것”을 제2006호에 분류하며, “삼투탈수 방식으로 보존처리한 경우에는 제2008호에 분류한다.”라고 규정하면서 제2006호에는 시럽에 넣어 끓이는 방식을 명시
A17: 13 | B17: =IF(케이스목록!$B17="","",케이스목록!$B17) -> 품목분류4과-945 | C17: =IF(케이스목록!$E17="","",케이스목록!$E17) -> ㅇ 물품개요 - CO₂가스를 동력원으로 화장품을 피부 표면에 미세하고 균일하게 분사하는 미용기기 - 분사 과정 중 화장품의 온도를 낮춰 피부에 쿨링감을 제공 ㅇ 주요 구성요소 및 기능 - 노즐 : CO₂가스를 제어하면서 분사 방향/각도 유지 - 냉각모듈 : 열전대소자(Peltier)*로, 화장품의 온도를 쿨링감있게 유지 * 전기를 흘리면 한쪽 면은 차가워지고 반대쪽 면은 뜨거워지는 열전소자 - 솔레노이드 밸브 : 전자제어 밸브로 가스 분사량 제어 - 디스플레이 : 배터리, 오류코드 등 상태 표시 - 트리거(방아쇠), USB-C 충전 포트, 리튬이온 배터리(3,350㎃h) 내장 등 - CO₂카트리지(미제시) : 고압 액화 CO₂가 밀봉된 소형 실린더 - 컨테이너(미제시) : 액상 화장품을 담는 용기 ㅇ 작동 원리 - 카트리지와 컨테이너 장착(미제시) → 트리거 작동 → 솔레노이드밸브가 개방되며 CO₂가스가 부품 내의 용기 안으로 이동 → 용기 내부 압력 상승 → 화장품이 노즐을 통해 약 45° 각도로 분사 - CO₂가스(극저온 냉매, -79도)의 분사로 화장품의 온도를 급속히 낮추고 이를 열전대(Peltier) 소자로 급속 가열하여 피부에 전달되는 온도(2~4도)로 유지 | D17: =IF(케이스목록!$D17="","",케이스목록!$D17) -> 8424209000 | E17: =IF(케이스목록!$H17="","",케이스목록!$H17) -> O | F17: X | G17: X | H17: 8424.20-0000 | I17: =IF(OR($D17="",$H17=""),"",IF(LEFT(SUBSTITUTE(SUBSTITUTE(SUBSTITUTE(SUBSTITUTE(SUBSTITUTE($D17,".",""),"-","")," ","")," ",""),CHAR(9),""),4)=LEFT(SUBSTITUTE(SUBSTITUTE(SUBSTITUTE(SUBSTITUTE(SUBSTITUTE($H17,".",""),"-","")," ","")," ",""),CHAR(9),""),4),1,0)) -> 1 | J17: =IF(OR($D17="",$H17=""),"",IF(LEFT(SUBSTITUTE(SUBSTITUTE(SUBSTITUTE(SUBSTITUTE(SUBSTITUTE($D17,".",""),"-","")," ","")," ",""),CHAR(9),""),6)=LEFT(SUBSTITUTE(SUBSTITUTE(SUBSTITUTE(SUBSTITUTE(SUBSTITUTE($H17,".",""),"-","")," ","")," ",""),CHAR(9),""),6),1,0)) -> 1 | K17: =IF(OR($D17="",$H17=""),"",IF(SUBSTITUTE(SUBSTITUTE(SUBSTITUTE(SUBSTITUTE(SUBSTITUTE($D17,".",""),"-","")," ","")," ",""),CHAR(9),"")=SUBSTITUTE(SUBSTITUTE(SUBSTITUTE(SUBSTITUTE(SUBSTITUTE($H17,".",""),"-","")," ","")," ",""),CHAR(9),""),1,0)) -> 0 | L17: 8424.20-0000 | M17: 8543.70-2020 | N17: 8424.89-9090 | O17: =IF(OR($D17="",$L17=""),"",IF(LEFT(SUBSTITUTE(SUBSTITUTE(SUBSTITUTE(SUBSTITUTE(SUBSTITUTE($D17,".",""),"-","")," ","")," ",""),CHAR(9),""),6)=LEFT(SUBSTITUTE(SUBSTITUTE(SUBSTITUTE(SUBSTITUTE(SUBSTITUTE($L17,".",""),"-","")," ","")," ",""),CHAR(9),""),6),1,0)) -> 1 | P17: =IF(OR($D17="",$L17=""),"",IF(OR(LEFT(SUBSTITUTE(SUBSTITUTE(SUBSTITUTE(SUBSTITUTE(SUBSTITUTE($D17,".",""),"-","")," ","")," ",""),CHAR(9),""),6)=LEFT(SUBSTITUTE(SUBSTITUTE(SUBSTITUTE(SUBSTITUTE(SUBSTITUTE($L17,".",""),"-","")," ","")," ",""),CHAR(9),""),6),LEFT(SUBSTITUTE(SUBSTITUTE(SUBSTITUTE(SUBSTITUTE(SUBSTITUTE($D17,".",""),"-","")," ","")," ",""),CHAR(9),""),6)=LEFT(SUBSTITUTE(SUBSTITUTE(SUBSTITUTE(SUBSTITUTE(SUBSTITUTE($M17,".",""),"-","")," ","")," ",""),CHAR(9),""),6),LEFT(SUBSTITUTE(SUBSTITUTE(SUBSTITUTE(SUBSTITUTE(SUBSTITUTE($D17,".",""),"-","")," ","")," ",""),CHAR(9),""),6)=LEFT(SUBSTITUTE(SUBSTITUTE(SUBSTITUTE(SUBSTITUTE(SUBSTITUTE($N17,".",""),"-","")," ","")," ",""),CHAR(9),""),6)),1,0)) -> 1 | Q17: 호 경합 판단 오류 | R17: 판단 어려움.
A18: 14 | B18: =IF(케이스목록!$B18="","",케이스목록!$B18) -> 품목분류1과-876 | C18: =IF(케이스목록!$E18="","",케이스목록!$E18) -> ㅇ 물품 개요 - 산업용 스마트카메라*의 일종인 In-sight Vision 장비에 전용되는 대물렌즈로, 측정 대상 물품의 상을 포착하여 후방(스마트 카메라 본체)에 위치한 CMOS 이미지 센서에 상을 맺게 함 * 일반적인 카메라와 달리 영상획득, 영상처리, 판단․제어 로직을 하나의 장치로 통합한 비전(vision) 측정검사 장비(제9031.4호에 분류되고 있음) ㅇ 구성 요소별 기능 ① 렌즈 : 일반렌즈와 액체 렌즈가 결합된 형태로, 포착된 피사체의 상을 스마트 카메라 본체 내부의 CMOS 이미지 센서 위에 결상시킴(본체의 CMOS 센서가 이를 디지털 신호로 변환하여 영상 데이터를 생성) ② 커넥터 : 액체 렌즈 부분의 셀을 형성하기 위해서 전력을 공급하고, 촬영 간 초점을 빠르게 전환하기 위한 제어 명령 전달 ③ 장착 부분 : Auto Focus 렌즈(쟁점물품)와 In-sight 제품(본체)을 연결하는 부분으로 인사이트 제품의 장착에 맞게 홈이 파여 있으며 제품을 연결하기 위해 볼트가 삽입된 연결부분이 있음. | D18: =IF(케이스목록!$D18="","",케이스목록!$D18) -> 9002119090 | E18: =IF(케이스목록!$H18="","",케이스목록!$H18) -> O | F18: X | G18: X | H18: 9002.19-9000 | I18: =IF(OR($D18="",$H18=""),"",IF(LEFT(SUBSTITUTE(SUBSTITUTE(SUBSTITUTE(SUBSTITUTE(SUBSTITUTE($D18,".",""),"-","")," ","")," ",""),CHAR(9),""),4)=LEFT(SUBSTITUTE(SUBSTITUTE(SUBSTITUTE(SUBSTITUTE(SUBSTITUTE($H18,".",""),"-","")," ","")," ",""),CHAR(9),""),4),1,0)) -> 1 | J18: =IF(OR($D18="",$H18=""),"",IF(LEFT(SUBSTITUTE(SUBSTITUTE(SUBSTITUTE(SUBSTITUTE(SUBSTITUTE($D18,".",""),"-","")," ","")," ",""),CHAR(9),""),6)=LEFT(SUBSTITUTE(SUBSTITUTE(SUBSTITUTE(SUBSTITUTE(SUBSTITUTE($H18,".",""),"-","")," ","")," ",""),CHAR(9),""),6),1,0)) -> 0 | K18: =IF(OR($D18="",$H18=""),"",IF(SUBSTITUTE(SUBSTITUTE(SUBSTITUTE(SUBSTITUTE(SUBSTITUTE($D18,".",""),"-","")," ","")," ",""),CHAR(9),"")=SUBSTITUTE(SUBSTITUTE(SUBSTITUTE(SUBSTITUTE(SUBSTITUTE($H18,".",""),"-","")," ","")," ",""),CHAR(9),""),1,0)) -> 0 | L18: 9002.19-9000 | M18: 9031.90-9000 | N18: 9002.11-0000 | O18: =IF(OR($D18="",$L18=""),"",IF(LEFT(SUBSTITUTE(SUBSTITUTE(SUBSTITUTE(SUBSTITUTE(SUBSTITUTE($D18,".",""),"-","")," ","")," ",""),CHAR(9),""),6)=LEFT(SUBSTITUTE(SUBSTITUTE(SUBSTITUTE(SUBSTITUTE(SUBSTITUTE($L18,".",""),"-","")," ","")," ",""),CHAR(9),""),6),1,0)) -> 0 | P18: =IF(OR($D18="",$L18=""),"",IF(OR(LEFT(SUBSTITUTE(SUBSTITUTE(SUBSTITUTE(SUBSTITUTE(SUBSTITUTE($D18,".",""),"-","")," ","")," ",""),CHAR(9),""),6)=LEFT(SUBSTITUTE(SUBSTITUTE(SUBSTITUTE(SUBSTITUTE(SUBSTITUTE($L18,".",""),"-","")," ","")," ",""),CHAR(9),""),6),LEFT(SUBSTITUTE(SUBSTITUTE(SUBSTITUTE(SUBSTITUTE(SUBSTITUTE($D18,".",""),"-","")," ","")," ",""),CHAR(9),""),6)=LEFT(SUBSTITUTE(SUBSTITUTE(SUBSTITUTE(SUBSTITUTE(SUBSTITUTE($M18,".",""),"-","")," ","")," ",""),CHAR(9),""),6),LEFT(SUBSTITUTE(SUBSTITUTE(SUBSTITUTE(SUBSTITUTE(SUBSTITUTE($D18,".",""),"-","")," ","")," ",""),CHAR(9),""),6)=LEFT(SUBSTITUTE(SUBSTITUTE(SUBSTITUTE(SUBSTITUTE(SUBSTITUTE($N18,".",""),"-","")," ","")," ",""),CHAR(9),""),6)),1,0)) -> 1 | Q18: 한국 고유 세번(10자리) 오류
A19: 15 | B19: =IF(케이스목록!$B19="","",케이스목록!$B19) -> 품목분류2과-1011 | C19: =IF(케이스목록!$E19="","",케이스목록!$E19) -> ㅇ 물품개요 - 살리실산을 주성분으로 한 황색 페이스트를 원형 스펀지 중앙에 채운 후 스트립상의 접착시트에 부착한 것을 소매포장한 것(내용량 : 100g, 12매/box) - 용도: 티눈, 굳은 살, 사마귀 제거(일반의약품) | D19: =IF(케이스목록!$D19="","",케이스목록!$D19) -> 3004909900 | E19: =IF(케이스목록!$H19="","",케이스목록!$H19) -> O | F19: X | G19: X | H19: 3005.10-9000 | I19: =IF(OR($D19="",$H19=""),"",IF(LEFT(SUBSTITUTE(SUBSTITUTE(SUBSTITUTE(SUBSTITUTE(SUBSTITUTE($D19,".",""),"-","")," ","")," ",""),CHAR(9),""),4)=LEFT(SUBSTITUTE(SUBSTITUTE(SUBSTITUTE(SUBSTITUTE(SUBSTITUTE($H19,".",""),"-","")," ","")," ",""),CHAR(9),""),4),1,0)) -> 0 | J19: =IF(OR($D19="",$H19=""),"",IF(LEFT(SUBSTITUTE(SUBSTITUTE(SUBSTITUTE(SUBSTITUTE(SUBSTITUTE($D19,".",""),"-","")," ","")," ",""),CHAR(9),""),6)=LEFT(SUBSTITUTE(SUBSTITUTE(SUBSTITUTE(SUBSTITUTE(SUBSTITUTE($H19,".",""),"-","")," ","")," ",""),CHAR(9),""),6),1,0)) -> 0 | K19: =IF(OR($D19="",$H19=""),"",IF(SUBSTITUTE(SUBSTITUTE(SUBSTITUTE(SUBSTITUTE(SUBSTITUTE($D19,".",""),"-","")," ","")," ",""),CHAR(9),"")=SUBSTITUTE(SUBSTITUTE(SUBSTITUTE(SUBSTITUTE(SUBSTITUTE($H19,".",""),"-","")," ","")," ",""),CHAR(9),""),1,0)) -> 0 | L19: 3005.10-9000 | M19: 3005.10-1000 | N19: 3004.90-9900 | O19: =IF(OR($D19="",$L19=""),"",IF(LEFT(SUBSTITUTE(SUBSTITUTE(SUBSTITUTE(SUBSTITUTE(SUBSTITUTE($D19,".",""),"-","")," ","")," ",""),CHAR(9),""),6)=LEFT(SUBSTITUTE(SUBSTITUTE(SUBSTITUTE(SUBSTITUTE(SUBSTITUTE($L19,".",""),"-","")," ","")," ",""),CHAR(9),""),6),1,0)) -> 0 | P19: =IF(OR($D19="",$L19=""),"",IF(OR(LEFT(SUBSTITUTE(SUBSTITUTE(SUBSTITUTE(SUBSTITUTE(SUBSTITUTE($D19,".",""),"-","")," ","")," ",""),CHAR(9),""),6)=LEFT(SUBSTITUTE(SUBSTITUTE(SUBSTITUTE(SUBSTITUTE(SUBSTITUTE($L19,".",""),"-","")," ","")," ",""),CHAR(9),""),6),LEFT(SUBSTITUTE(SUBSTITUTE(SUBSTITUTE(SUBSTITUTE(SUBSTITUTE($D19,".",""),"-","")," ","")," ",""),CHAR(9),""),6)=LEFT(SUBSTITUTE(SUBSTITUTE(SUBSTITUTE(SUBSTITUTE(SUBSTITUTE($M19,".",""),"-","")," ","")," ",""),CHAR(9),""),6),LEFT(SUBSTITUTE(SUBSTITUTE(SUBSTITUTE(SUBSTITUTE(SUBSTITUTE($D19,".",""),"-","")," ","")," ",""),CHAR(9),""),6)=LEFT(SUBSTITUTE(SUBSTITUTE(SUBSTITUTE(SUBSTITUTE(SUBSTITUTE($N19,".",""),"-","")," ","")," ",""),CHAR(9),""),6)),1,0)) -> 1 | Q19: 호 경합 판단 오류 | R19: 성분이 살리실산이라는 점에만 주목할 경우 발생할 수 있는 후보
A20: 16 | B20: =IF(케이스목록!$B20="","",케이스목록!$B20) -> 품목분류2과-1000 | C20: =IF(케이스목록!$E20="","",케이스목록!$E20) -> ㅇ 물품개요 - 불활성화 A형 간염 바이러스 항원을 안정제, 보존제, 주사용수 등에 혼합하여 조제한 투명 액상을 주사기(몸체) 모양 용기에 소매 포장하여 냉동한 것(내용량: 1000㎕) - 용도 : 효소결합면역흡착측정(ELISA)*분석 시 사용되는 기준물질(내부 대조군) * 항원-항체 반응을 이용하여 항원이나 항체의 양을 측정하는 분석법 | D20: =IF(케이스목록!$D20="","",케이스목록!$D20) -> 3002494000 | E20: =IF(케이스목록!$H20="","",케이스목록!$H20) -> O | F20: X | G20: X | H20: 3822.19-9000 | I20: =IF(OR($D20="",$H20=""),"",IF(LEFT(SUBSTITUTE(SUBSTITUTE(SUBSTITUTE(SUBSTITUTE(SUBSTITUTE($D20,".",""),"-","")," ","")," ",""),CHAR(9),""),4)=LEFT(SUBSTITUTE(SUBSTITUTE(SUBSTITUTE(SUBSTITUTE(SUBSTITUTE($H20,".",""),"-","")," ","")," ",""),CHAR(9),""),4),1,0)) -> 0 | J20: =IF(OR($D20="",$H20=""),"",IF(LEFT(SUBSTITUTE(SUBSTITUTE(SUBSTITUTE(SUBSTITUTE(SUBSTITUTE($D20,".",""),"-","")," ","")," ",""),CHAR(9),""),6)=LEFT(SUBSTITUTE(SUBSTITUTE(SUBSTITUTE(SUBSTITUTE(SUBSTITUTE($H20,".",""),"-","")," ","")," ",""),CHAR(9),""),6),1,0)) -> 0 | K20: =IF(OR($D20="",$H20=""),"",IF(SUBSTITUTE(SUBSTITUTE(SUBSTITUTE(SUBSTITUTE(SUBSTITUTE($D20,".",""),"-","")," ","")," ",""),CHAR(9),"")=SUBSTITUTE(SUBSTITUTE(SUBSTITUTE(SUBSTITUTE(SUBSTITUTE($H20,".",""),"-","")," ","")," ",""),CHAR(9),""),1,0)) -> 0 | L20: 3822.19-9000 | M20: 3822.19-1000 | N20: 3002.49-9000 | O20: =IF(OR($D20="",$L20=""),"",IF(LEFT(SUBSTITUTE(SUBSTITUTE(SUBSTITUTE(SUBSTITUTE(SUBSTITUTE($D20,".",""),"-","")," ","")," ",""),CHAR(9),""),6)=LEFT(SUBSTITUTE(SUBSTITUTE(SUBSTITUTE(SUBSTITUTE(SUBSTITUTE($L20,".",""),"-","")," ","")," ",""),CHAR(9),""),6),1,0)) -> 0 | P20: =IF(OR($D20="",$L20=""),"",IF(OR(LEFT(SUBSTITUTE(SUBSTITUTE(SUBSTITUTE(SUBSTITUTE(SUBSTITUTE($D20,".",""),"-","")," ","")," ",""),CHAR(9),""),6)=LEFT(SUBSTITUTE(SUBSTITUTE(SUBSTITUTE(SUBSTITUTE(SUBSTITUTE($L20,".",""),"-","")," ","")," ",""),CHAR(9),""),6),LEFT(SUBSTITUTE(SUBSTITUTE(SUBSTITUTE(SUBSTITUTE(SUBSTITUTE($D20,".",""),"-","")," ","")," ",""),CHAR(9),""),6)=LEFT(SUBSTITUTE(SUBSTITUTE(SUBSTITUTE(SUBSTITUTE(SUBSTITUTE($M20,".",""),"-","")," ","")," ",""),CHAR(9),""),6),LEFT(SUBSTITUTE(SUBSTITUTE(SUBSTITUTE(SUBSTITUTE(SUBSTITUTE($D20,".",""),"-","")," ","")," ",""),CHAR(9),""),6)=LEFT(SUBSTITUTE(SUBSTITUTE(SUBSTITUTE(SUBSTITUTE(SUBSTITUTE($N20,".",""),"-","")," ","")," ",""),CHAR(9),""),6)),1,0)) -> 1 | Q20: 물품설명 정보 부족 | R20: 수입 시점의 정확한 성분 비율, 제조 공정, 공인된 기준물질(CRM) 인증서 유무 등에 따라 달라질 수 있으므로, 정확한 수입통관
A21: 17 | B21: =IF(케이스목록!$B21="","",케이스목록!$B21) -> 품목분류2과-254 | C21: =IF(케이스목록!$E21="","",케이스목록!$E21) -> o Propanediol(92.5%), Caprylhydroxamic acid(7.5%)로 혼합‧조제된 무색투명 액상 - 용도 : 화장품 제조용 보존제(0.5～1.0% 사용) | D21: =IF(케이스목록!$D21="","",케이스목록!$D21) -> 3808999000 | E21: =IF(케이스목록!$H21="","",케이스목록!$H21) -> O | F21: X | G21: X | H21: 3824.99-9090 | I21: =IF(OR($D21="",$H21=""),"",IF(LEFT(SUBSTITUTE(SUBSTITUTE(SUBSTITUTE(SUBSTITUTE(SUBSTITUTE($D21,".",""),"-","")," ","")," ",""),CHAR(9),""),4)=LEFT(SUBSTITUTE(SUBSTITUTE(SUBSTITUTE(SUBSTITUTE(SUBSTITUTE($H21,".",""),"-","")," ","")," ",""),CHAR(9),""),4),1,0)) -> 0 | J21: =IF(OR($D21="",$H21=""),"",IF(LEFT(SUBSTITUTE(SUBSTITUTE(SUBSTITUTE(SUBSTITUTE(SUBSTITUTE($D21,".",""),"-","")," ","")," ",""),CHAR(9),""),6)=LEFT(SUBSTITUTE(SUBSTITUTE(SUBSTITUTE(SUBSTITUTE(SUBSTITUTE($H21,".",""),"-","")," ","")," ",""),CHAR(9),""),6),1,0)) -> 0 | K21: =IF(OR($D21="",$H21=""),"",IF(SUBSTITUTE(SUBSTITUTE(SUBSTITUTE(SUBSTITUTE(SUBSTITUTE($D21,".",""),"-","")," ","")," ",""),CHAR(9),"")=SUBSTITUTE(SUBSTITUTE(SUBSTITUTE(SUBSTITUTE(SUBSTITUTE($H21,".",""),"-","")," ","")," ",""),CHAR(9),""),1,0)) -> 0 | L21: 3824.99-9090 | M21: 3808.94-0000 | N21: 2905.39-9000 | O21: =IF(OR($D21="",$L21=""),"",IF(LEFT(SUBSTITUTE(SUBSTITUTE(SUBSTITUTE(SUBSTITUTE(SUBSTITUTE($D21,".",""),"-","")," ","")," ",""),CHAR(9),""),6)=LEFT(SUBSTITUTE(SUBSTITUTE(SUBSTITUTE(SUBSTITUTE(SUBSTITUTE($L21,".",""),"-","")," ","")," ",""),CHAR(9),""),6),1,0)) -> 0 | P21: =IF(OR($D21="",$L21=""),"",IF(OR(LEFT(SUBSTITUTE(SUBSTITUTE(SUBSTITUTE(SUBSTITUTE(SUBSTITUTE($D21,".",""),"-","")," ","")," ",""),CHAR(9),""),6)=LEFT(SUBSTITUTE(SUBSTITUTE(SUBSTITUTE(SUBSTITUTE(SUBSTITUTE($L21,".",""),"-","")," ","")," ",""),CHAR(9),""),6),LEFT(SUBSTITUTE(SUBSTITUTE(SUBSTITUTE(SUBSTITUTE(SUBSTITUTE($D21,".",""),"-","")," ","")," ",""),CHAR(9),""),6)=LEFT(SUBSTITUTE(SUBSTITUTE(SUBSTITUTE(SUBSTITUTE(SUBSTITUTE($M21,".",""),"-","")," ","")," ",""),CHAR(9),""),6),LEFT(SUBSTITUTE(SUBSTITUTE(SUBSTITUTE(SUBSTITUTE(SUBSTITUTE($D21,".",""),"-","")," ","")," ",""),CHAR(9),""),6)=LEFT(SUBSTITUTE(SUBSTITUTE(SUBSTITUTE(SUBSTITUTE(SUBSTITUTE($N21,".",""),"-","")," ","")," ",""),CHAR(9),""),6)),1,0)) -> 0 | Q21: 호 경합 판단 오류 | R21: 물품설명과 같이 조제되어 화장품 등의 보존제로 사용되는 물품이므로 “살균제·소독제와 유사한 물품”으로 보아
A22: 18 | B22: =IF(케이스목록!$B22="","",케이스목록!$B22) -> 품목분류1과-1222 | C22: =IF(케이스목록!$E22="","",케이스목록!$E22) -> ㅇ 물품개요 - 맥주병박스 형상의 병따개를 들고 있는 두꺼비 형상의 피규어로, 병따개와 피규어에 해당 브랜드 주류의 로고(“TERRA”, “진로”)가 인쇄되어 있음 ※ 피규어: 다양한 동작을 표현할 수 있도록 관절이 움직일 수 있게 만들어 놓은, 인간이나 동물 형상의 장난감 (출처: 고려대 한국어대사전) - 병따개는 피규어로부터 수시로 탈부착 가능(병따개 사용 시 피규어로부터 분리하여 단독으로 사용하여야 함) ※ 사전심사 신청시 제시견본은 병따개가 피규어의 손에 접착제로 붙어있는 상태로 제시되었으나, 업체로부터 제시상태를 재확인한 결과, 병따개를 피규어로부터 수시로 탈부착할 수 있는 상태로 제시상태를 확정함. - 현재 시중에 해당 브랜드의 두꺼비 캐릭터 굿즈가 다양하게 판매되고 있으나, 본 물품의 피규어와 동일한 형상의 피규어가 병따개 없이 단독으로 판매되고 있지는 않음 | D22: =IF(케이스목록!$D22="","",케이스목록!$D22) -> 8205510000 | E22: =IF(케이스목록!$H22="","",케이스목록!$H22) -> O | F22: X | G22: X | H22: 9503.00-3200 | I22: =IF(OR($D22="",$H22=""),"",IF(LEFT(SUBSTITUTE(SUBSTITUTE(SUBSTITUTE(SUBSTITUTE(SUBSTITUTE($D22,".",""),"-","")," ","")," ",""),CHAR(9),""),4)=LEFT(SUBSTITUTE(SUBSTITUTE(SUBSTITUTE(SUBSTITUTE(SUBSTITUTE($H22,".",""),"-","")," ","")," ",""),CHAR(9),""),4),1,0)) -> 0 | J22: =IF(OR($D22="",$H22=""),"",IF(LEFT(SUBSTITUTE(SUBSTITUTE(SUBSTITUTE(SUBSTITUTE(SUBSTITUTE($D22,".",""),"-","")," ","")," ",""),CHAR(9),""),6)=LEFT(SUBSTITUTE(SUBSTITUTE(SUBSTITUTE(SUBSTITUTE(SUBSTITUTE($H22,".",""),"-","")," ","")," ",""),CHAR(9),""),6),1,0)) -> 0 | K22: =IF(OR($D22="",$H22=""),"",IF(SUBSTITUTE(SUBSTITUTE(SUBSTITUTE(SUBSTITUTE(SUBSTITUTE($D22,".",""),"-","")," ","")," ",""),CHAR(9),"")=SUBSTITUTE(SUBSTITUTE(SUBSTITUTE(SUBSTITUTE(SUBSTITUTE($H22,".",""),"-","")," ","")," ",""),CHAR(9),""),1,0)) -> 0 | L22: 9503.00-3200 | M22: 8205.51-0000 | N22: 3926.90-9000 | O22: =IF(OR($D22="",$L22=""),"",IF(LEFT(SUBSTITUTE(SUBSTITUTE(SUBSTITUTE(SUBSTITUTE(SUBSTITUTE($D22,".",""),"-","")," ","")," ",""),CHAR(9),""),6)=LEFT(SUBSTITUTE(SUBSTITUTE(SUBSTITUTE(SUBSTITUTE(SUBSTITUTE($L22,".",""),"-","")," ","")," ",""),CHAR(9),""),6),1,0)) -> 0 | P22: =IF(OR($D22="",$L22=""),"",IF(OR(LEFT(SUBSTITUTE(SUBSTITUTE(SUBSTITUTE(SUBSTITUTE(SUBSTITUTE($D22,".",""),"-","")," ","")," ",""),CHAR(9),""),6)=LEFT(SUBSTITUTE(SUBSTITUTE(SUBSTITUTE(SUBSTITUTE(SUBSTITUTE($L22,".",""),"-","")," ","")," ",""),CHAR(9),""),6),LEFT(SUBSTITUTE(SUBSTITUTE(SUBSTITUTE(SUBSTITUTE(SUBSTITUTE($D22,".",""),"-","")," ","")," ",""),CHAR(9),""),6)=LEFT(SUBSTITUTE(SUBSTITUTE(SUBSTITUTE(SUBSTITUTE(SUBSTITUTE($M22,".",""),"-","")," ","")," ",""),CHAR(9),""),6),LEFT(SUBSTITUTE(SUBSTITUTE(SUBSTITUTE(SUBSTITUTE(SUBSTITUTE($D22,".",""),"-","")," ","")," ",""),CHAR(9),""),6)=LEFT(SUBSTITUTE(SUBSTITUTE(SUBSTITUTE(SUBSTITUTE(SUBSTITUTE($N22,".",""),"-","")," ","")," ",""),CHAR(9),""),6)),1,0)) -> 1 | Q22: 용도/기능 오인 | R22: 동물이나 인간이 아닌 창조물을 형상화한 완구
A23: 19 | B23: =IF(케이스목록!$B23="","",케이스목록!$B23) -> 품목분류3과-665 | C23: =IF(케이스목록!$E23="","",케이스목록!$E23) -> ㅇ 물품개요 - PVC 원단과 PE 시트를 적층한 롤 상의 매트(1100×3000×16mm) - 용도 : 운동 및 놀이 시 층간소음방지, 미끄럼방지 및 충격완화 ㅇ 제조공정 - 무가교+화학가교 PE 시트 합지 → 논슬립 PE 필름 합지 → 발포 PVC 원단 합지 → 폭 컷팅 → 권취 및 숙성 → 길이 재단 → 포장 | D23: =IF(케이스목록!$D23="","",케이스목록!$D23) -> 3918101000 | E23: =IF(케이스목록!$H23="","",케이스목록!$H23) -> O | F23: X | G23: X | H23: 3918.10-9000 | I23: =IF(OR($D23="",$H23=""),"",IF(LEFT(SUBSTITUTE(SUBSTITUTE(SUBSTITUTE(SUBSTITUTE(SUBSTITUTE($D23,".",""),"-","")," ","")," ",""),CHAR(9),""),4)=LEFT(SUBSTITUTE(SUBSTITUTE(SUBSTITUTE(SUBSTITUTE(SUBSTITUTE($H23,".",""),"-","")," ","")," ",""),CHAR(9),""),4),1,0)) -> 1 | J23: =IF(OR($D23="",$H23=""),"",IF(LEFT(SUBSTITUTE(SUBSTITUTE(SUBSTITUTE(SUBSTITUTE(SUBSTITUTE($D23,".",""),"-","")," ","")," ",""),CHAR(9),""),6)=LEFT(SUBSTITUTE(SUBSTITUTE(SUBSTITUTE(SUBSTITUTE(SUBSTITUTE($H23,".",""),"-","")," ","")," ",""),CHAR(9),""),6),1,0)) -> 1 | K23: =IF(OR($D23="",$H23=""),"",IF(SUBSTITUTE(SUBSTITUTE(SUBSTITUTE(SUBSTITUTE(SUBSTITUTE($D23,".",""),"-","")," ","")," ",""),CHAR(9),"")=SUBSTITUTE(SUBSTITUTE(SUBSTITUTE(SUBSTITUTE(SUBSTITUTE($H23,".",""),"-","")," ","")," ",""),CHAR(9),""),1,0)) -> 0 | L23: 3918.10-9000 | M23: 3918.90-9000 | N23: 9506.91-0000 | O23: =IF(OR($D23="",$L23=""),"",IF(LEFT(SUBSTITUTE(SUBSTITUTE(SUBSTITUTE(SUBSTITUTE(SUBSTITUTE($D23,".",""),"-","")," ","")," ",""),CHAR(9),""),6)=LEFT(SUBSTITUTE(SUBSTITUTE(SUBSTITUTE(SUBSTITUTE(SUBSTITUTE($L23,".",""),"-","")," ","")," ",""),CHAR(9),""),6),1,0)) -> 1 | P23: =IF(OR($D23="",$L23=""),"",IF(OR(LEFT(SUBSTITUTE(SUBSTITUTE(SUBSTITUTE(SUBSTITUTE(SUBSTITUTE($D23,".",""),"-","")," ","")," ",""),CHAR(9),""),6)=LEFT(SUBSTITUTE(SUBSTITUTE(SUBSTITUTE(SUBSTITUTE(SUBSTITUTE($L23,".",""),"-","")," ","")," ",""),CHAR(9),""),6),LEFT(SUBSTITUTE(SUBSTITUTE(SUBSTITUTE(SUBSTITUTE(SUBSTITUTE($D23,".",""),"-","")," ","")," ",""),CHAR(9),""),6)=LEFT(SUBSTITUTE(SUBSTITUTE(SUBSTITUTE(SUBSTITUTE(SUBSTITUTE($M23,".",""),"-","")," ","")," ",""),CHAR(9),""),6),LEFT(SUBSTITUTE(SUBSTITUTE(SUBSTITUTE(SUBSTITUTE(SUBSTITUTE($D23,".",""),"-","")," ","")," ",""),CHAR(9),""),6)=LEFT(SUBSTITUTE(SUBSTITUTE(SUBSTITUTE(SUBSTITUTE(SUBSTITUTE($N23,".",""),"-","")," ","")," ",""),CHAR(9),""),6)),1,0)) -> 1 | Q23: 물품설명 정보 부족 | R23: HS 6단위 소호 분류 시, 구성 재료의 역할 면에서 PVC가 충격 흡수에 우수하고, 일반적으로 바닥에 깔고 사용하는 바닥 깔개는 신체와 접촉하는 노출 표면이 중요하게 여겨지며, 또한 구성 재료의 가격, 중량 측면에서 PE보다 PVC가 더 큰 비중을 차지함 ‧ 더구나, 일반적으로 바닥 깔개의 충진재(바닥재)는 주로 물품의 형태 유지나 보강의 목적으로 사용하는 경우가 많음 ‧ 즉, 바닥 깔개의 본질적인 특성은 구성 재료의 역할, 가격, 중량에 따라 PVC 노출 표면에 있는 것으로 판단됨 - 따라서 본 물품을 ‘폴리염화비닐로 만든 바닥깔개’로 보아
A24: 20 | B24: =IF(케이스목록!$B24="","",케이스목록!$B24) -> 품목분류1과-227 | C24: =IF(케이스목록!$E24="","",케이스목록!$E24) -> ㅇ 물품개요 - 냉장, 냉동, 김치냉장고로 변온 가능한 1도어 냉동/냉장고로 외부에 온도를 조절할 수 있는 디스플레이*가 설치되어 있음 * 디스플레이 터치패널에 냉동/냉장기능을 선택할 수 있는 ‘온도설정’ 버튼과 김치냉장고로 기능을 전환하는 ‘김치저장’ 버튼이 있음 - 냉동은 –17℃∼-23℃ 사이, 냉장은 5℃∼0℃에서 조절함(온도 설정 버튼으로 전환) - 규격 : 455 × 1,853 × 685㎜, 용량 : 240ℓ ㅇ 주요 구성요소 - 압축기 : 냉매를 고압 상태로 압축함 - 응축기 : 고온 고압 냉매를 응축시킴 - 증발기 : 냉매 증발로 - Cabinet : 저온의 온도를 유지하기 위한 본체(단열재 두께 55㎜) - Door : 내용물을 넣고 빼고 할 수 있는 도어 ㅇ 기능 ① 냉동 : 냉동 온도를 유지할 수 있는 단열재 두께(55㎜)*를 가진 Cabinet과 냉각 능력의 압축기**로 구성됨 * 냉장고 Cabinet의 경우 일반적으로 40㎜ 내외의 단열재 두께를 가짐 ** 190㎉/Hr 출력의 냉매 용량 11㏄급 압축기가 설치되어 있으며, 해당 압축기가 상시 작동하여 냉매를 압축시키고 증발기를 통해 냉매를 기화시켜 냉동 온도(–17℃∼-23℃)를 유지할 수 있도록 냉각함 ② 냉장, 김치 : 냉장 설정하는 경우 3℃, 김치 설정의 경우 0℃∼1℃를 유지할 수 있도록 압축기를 On/Off 하여 목표 온도에 도달하면 압축기가 정지하고, 기준 온도를 벗어나면 다시 압축기가 작동하여 고내 온도를 유지 (압축기를 냉동기능 활용 시에 비해 저 RPM으로 회전시켜 효율을 극대화) | D24: =IF(케이스목록!$D24="","",케이스목록!$D24) -> 8418400000 | E24: =IF(케이스목록!$H24="","",케이스목록!$H24) -> O | F24: X | G24: X | H24: 8418.40-1000 | I24: =IF(OR($D24="",$H24=""),"",IF(LEFT(SUBSTITUTE(SUBSTITUTE(SUBSTITUTE(SUBSTITUTE(SUBSTITUTE($D24,".",""),"-","")," ","")," ",""),CHAR(9),""),4)=LEFT(SUBSTITUTE(SUBSTITUTE(SUBSTITUTE(SUBSTITUTE(SUBSTITUTE($H24,".",""),"-","")," ","")," ",""),CHAR(9),""),4),1,0)) -> 1 | J24: =IF(OR($D24="",$H24=""),"",IF(LEFT(SUBSTITUTE(SUBSTITUTE(SUBSTITUTE(SUBSTITUTE(SUBSTITUTE($D24,".",""),"-","")," ","")," ",""),CHAR(9),""),6)=LEFT(SUBSTITUTE(SUBSTITUTE(SUBSTITUTE(SUBSTITUTE(SUBSTITUTE($H24,".",""),"-","")," ","")," ",""),CHAR(9),""),6),1,0)) -> 1 | K24: =IF(OR($D24="",$H24=""),"",IF(SUBSTITUTE(SUBSTITUTE(SUBSTITUTE(SUBSTITUTE(SUBSTITUTE($D24,".",""),"-","")," ","")," ",""),CHAR(9),"")=SUBSTITUTE(SUBSTITUTE(SUBSTITUTE(SUBSTITUTE(SUBSTITUTE($H24,".",""),"-","")," ","")," ",""),CHAR(9),""),1,0)) -> 0 | L24: 8418.40-1000 | M24: 8418.21-9010 | N24: 8418.21-9090 | O24: =IF(OR($D24="",$L24=""),"",IF(LEFT(SUBSTITUTE(SUBSTITUTE(SUBSTITUTE(SUBSTITUTE(SUBSTITUTE($D24,".",""),"-","")," ","")," ",""),CHAR(9),""),6)=LEFT(SUBSTITUTE(SUBSTITUTE(SUBSTITUTE(SUBSTITUTE(SUBSTITUTE($L24,".",""),"-","")," ","")," ",""),CHAR(9),""),6),1,0)) -> 1 | P24: =IF(OR($D24="",$L24=""),"",IF(OR(LEFT(SUBSTITUTE(SUBSTITUTE(SUBSTITUTE(SUBSTITUTE(SUBSTITUTE($D24,".",""),"-","")," ","")," ",""),CHAR(9),""),6)=LEFT(SUBSTITUTE(SUBSTITUTE(SUBSTITUTE(SUBSTITUTE(SUBSTITUTE($L24,".",""),"-","")," ","")," ",""),CHAR(9),""),6),LEFT(SUBSTITUTE(SUBSTITUTE(SUBSTITUTE(SUBSTITUTE(SUBSTITUTE($D24,".",""),"-","")," ","")," ",""),CHAR(9),""),6)=LEFT(SUBSTITUTE(SUBSTITUTE(SUBSTITUTE(SUBSTITUTE(SUBSTITUTE($M24,".",""),"-","")," ","")," ",""),CHAR(9),""),6),LEFT(SUBSTITUTE(SUBSTITUTE(SUBSTITUTE(SUBSTITUTE(SUBSTITUTE($D24,".",""),"-","")," ","")," ",""),CHAR(9),""),6)=LEFT(SUBSTITUTE(SUBSTITUTE(SUBSTITUTE(SUBSTITUTE(SUBSTITUTE($N24,".",""),"-","")," ","")," ",""),CHAR(9),""),6)),1,0)) -> 1 | Q24: 한국 고유 세번(10자리) 오류
